Workbook

Sheet 千牛数据
A1: 统计日期 | B1: 商品ID | C1: 商品名称 | D1: 主商品ID | E1: 商品类型 | F1: 货号 | G1: 商品状态 | H1: 商品标签 | I1: 商品访客数 | J1: 商品浏览量 | K1: 平均停留时长 | L1: 商品详情页跳出率 | M1: 商品收藏人数 | N1: 商品加购件数 | O1: 商品加购人数 | P1: 下单买家数 | Q1: 下单件数 | R1: 下单金额 | S1: 下单转化率 | T1: 支付买家数 | U1: 支付件数 | V1: 支付金额 | W1: 商品支付转化率 | X1: 支付新买家数 | Y1: 支付老买家数 | Z1: 老买家支付金额 | AA1: 聚划算支付金额 | AB1: 访客平均价值 | AC1: 成功退款金额 | AD1: 竞争力评分 | AE1: 年累计支付金额 | AF1: 月累计支付金额 | AG1: 月累计支付件数 | AH1: 搜索引导支付转化率 | AI1: 搜索引导访客数 | AJ1: 搜索引导支付买家数 | AK1: 结构化详情引导转化率 | AL1: 结构化详情引导成交占比
A2: 2026-01-01 | B2: 969105067992 | C2: LENNEA气质大毛领羽绒服外套女秋冬季连帽毛呢上衣小个子夹棉保暖 | D2: '969105067992 | E2: 主商品 | F2: 2025895 | G2: 当前在线 | H2: - | I2: 6560 | J2: 25528 | K2: 5.09 | L2: 0.6017 | M2: 220 | N2: 427 | O2: 400 | P2: 90 | Q2: 105 | R2: 30088 | S2: 0.0137 | T2: 80 | U2: 86 | V2: 24642 | W2: 0.0122 | X2: 75 | Y2: 5 | Z2: 2206 | AA2: 0 | AB2: 3.76 | AC2: 15685.2 | AD2: - | AE2: 24642 | AF2: 24642 | AG2: 86 | AH2: 0.026 | AI2: 845 | AJ2: 22 | AK2: - | AL2: -
A3: 2026-01-01 | B3: 973083694338 | C3: LENNEA连帽毛领棉服宽松简约棉衣冬季短款羽绒服面包服外套上衣女 | D3: '973083694338 | E3: 主商品 | F3: 2025890 | G3: 当前在线 | H3: - | I3: 2447 | J3: 6563 | K3: 5.89 | L3: 0.5954 | M3: 64 | N3: 124 | O3: 115 | P3: 25 | Q3: 28 | R3: 8689 | S3: 0.0102 | T3: 23 | U3: 25 | V3: 7879 | W3: 0.0094 | X3: 23 | Y3: 0 | Z3: 0 | AA3: 0 | AB3: 3.22 | AC3: 5302 | AD3: - | AE3: 7879 | AF3: 7879 | AG3: 25 | AH3: 0.0385 | AI3: 182 | AJ3: 7 | AK3: - | AL3: -
A4: 2026-01-01 | B4: 825735521554 | C4: LENNEA原创基础高立领面包服冬季通勤简约百搭宽松棉服保暖外套 | D4: '825735521554 | E4: 主商品 | F4: 2024878 | G4: 当前在线 | H4: - | I4: 2367 | J4: 6316 | K4: 7.21 | L4: 0.6527 | M4: 50 | N4: 91 | O4: 86 | P4: 20 | Q4: 24 | R4: 5256 | S4: 0.0084 | T4: 19 | U4: 20 | V4: 4380 | W4: 0.008 | X4: 19 | Y4: 0 | Z4: 0 | AA4: 0 | AB4: 1.85 | AC4: 2190 | AD4: - | AE4: 4380 | AF4: 4380 | AG4: 20 | AH4: 0.0282 | AI4: 177 | AJ4: 5 | AK4: - | AL4: -
A5: 2026-01-01 | B5: 970286397535 | C5: LENNEA小香风白色外套女秋冬2025新款深秋初冬高级短款羊毛感上衣 | D5: '970286397535 | E5: 主商品 | F5: - | G5: 当前在线 | H5: - | I5: 3257 | J5: 9039 | K5: 4.04 | L5: 0.6171 | M5: 76 | N5: 116 | O5: 109 | P5: 19 | Q5: 20 | R5: 5240 | S5: 0.0058 | T5: 15 | U5: 16 | V5: 4248 | W5: 0.0046 | X5: 13 | Y5: 2 | Z5: 636 | AA5: 0 | AB5: 1.3 | AC5: 4636 | AD5: - | AE5: 4248 | AF5: 4248 | AG5: 16 | AH5: 0.0397 | AI5: 126 | AJ5: 5 | AK5: - | AL5: -
A6: 2026-01-01 | B6: 972548387983 | C6: LENNEA藏青色毛领连帽棉服女冬季新款宽松保暖小个子百搭棉衣外套 | D6: '972548387983 | E6: 主商品 | F6: 2025918 | G6: 当前在线 | H6: - | I6: 1869 | J6: 3858 | K6: 4.61 | L6: 0.6207 | M6: 26 | N6: 64 | O6: 61 | P6: 15 | Q6: 17 | R6: 4590 | S6: 0.008 | T6: 14 | U6: 15 | V6: 4050 | W6: 0.0075 | X6: 13 | Y6: 1 | Z6: 270 | AA6: 0 | AB6: 2.17 | AC6: 2970 | AD6: - | AE6: 4050 | AF6: 4050 | AG6: 15 | AH6: 0.0377 | AI6: 53 | AJ6: 2 | AK6: - | AL6: -
A7: 2026-01-01 | B7: 987923069100 | C7: LENNEA高级感千金风金扣双面呢大衣女冬新款毛呢外套中长款小个子 | D7: '987923069100 | E7: 主商品 | F7: 2025302 | G7: 当前在线 | H7: - | I7: 1425 | J7: 4681 | K7: 4.35 | L7: 0.3509 | M7: 28 | N7: 117 | O7: 115 | P7: 12 | Q7: 12 | R7: 3588 | S7: 0.0084 | T7: 11 | U7: 11 | V7: 3289 | W7: 0.0077 | X7: 10 | Y7: 1 | Z7: 299 | AA7: 0 | AB7: 2.31 | AC7: 3588 | AD7: - | AE7: 3289 | AF7: 3289 | AG7: 11 | AH7: 0.0066 | AI7: 151 | AJ7: 1 | AK7: - | AL7: -
A8: 2026-01-01 | B8: 974433252366 | C8: LENNEA黑色短款木耳边棉服女韩系百搭面包服棉衣宽松休闲外套 | D8: '974433252366 | E8: 主商品 | F8: 2025902 | G8: 当前在线 | H8: - | I8: 3121 | J8: 6815 | K8: 4.37 | L8: 0.7107 | M8: 36 | N8: 77 | O8: 75 | P8: 12 | Q8: 13 | R8: 3094 | S8: 0.0038 | T8: 12 | U8: 12 | V8: 2856 | W8: 0.0038 | X8: 11 | Y8: 1 | Z8: 238 | AA8: 0 | AB8: 0.92 | AC8: 1190 | AD8: - | AE8: 2856 | AF8: 2856 | AG8: 12 | AH8: 0.0138 | AI8: 145 | AJ8: 2 | AK8: - | AL8: -
A9: 2026-01-01 | B9: 987169874467 | C9: LENNEA毛领双排扣短款毛呢羊毛大衣连帽外套女收腰秋冬加厚上衣 | D9: '987169874467 | E9: 主商品 | F9: 2025998 | G9: 当前在线 | H9: - | I9: 757 | J9: 2107 | K9: 6.48 | L9: 0.4518 | M9: 14 | N9: 63 | O9: 61 | P9: 8 | Q9: 10 | R9: 3090 | S9: 0.0106 | T9: 8 | U9: 9 | V9: 2781 | W9: 0.0106 | X9: 6 | Y9: 2 | Z9: 927 | AA9: 0 | AB9: 3.67 | AC9: 4017 | AD9: - | AE9: 2781 | AF9: 2781 | AG9: 9 | AH9: 0.0411 | AI9: 73 | AJ9: 3 | AK9: - | AL9: -
A10: 2026-01-01 | B10: 974413116307 | C10: LENNEA立领短款高腰棉服女冬季新款厚外套面包服棉袄纯色简约上衣 | D10: '974413116307 | E10: 主商品 | F10: 2025892 | G10: 当前在线 | H10: - | I10: 1056 | J10: 2243 | K10: 4.71 | L10: 0.5843 | M10: 17 | N10: 30 | O10: 30 | P10: 10 | Q10: 11 | R10: 2409 | S10: 0.0095 | T10: 11 | U10: 11 | V10: 2409 | W10: 0.0104 | X10: 10 | Y10: 1 | Z10: 219 | AA10: 0 | AB10: 2.28 | AC10: 2190 | AD10: - | AE10: 2409 | AF10: 2409 | AG10: 11 | AH10: 0.023 | AI10: 87 | AJ10: 2 | AK10: - | AL10: -
A11: 2026-01-01 | B11: 992234348721 | C11: LENNEA冬季新款绞花针织拼接长袖波点棉服女上衣保暖短外套棉衣 | D11: '992234348721 | E11: 主商品 | F11: 2025991 | G11: 当前在线 | H11: - | I11: 1890 | J11: 4361 | K11: 4.25 | L11: 0.6169 | M11: 47 | N11: 102 | O11: 100 | P11: 9 | Q11: 9 | R11: 2691 | S11: 0.0048 | T11: 8 | U11: 8 | V11: 2392 | W11: 0.0042 | X11: 8 | Y11: 0 | Z11: 0 | AA11: 0 | AB11: 1.27 | AC11: 1495 | AD11: - | AE11: 2392 | AF11: 2392 | AG11: 8 | AH11: 0.0256 | AI11: 117 | AJ11: 3 | AK11: - | AL11: -
A12: 2026-01-01 | B12: 986610503692 | C12: LENNEA毛毛外套女冬季短款翻领正肩皮毛一体环保毛皮草上衣女冬 | D12: '986610503692 | E12: 主商品 | F12: 2025997 | G12: 当前在线 | H12: - | I12: 927 | J12: 2338 | K12: 4.63 | L12: 0.5599 | M12: 16 | N12: 56 | O12: 53 | P12: 6 | Q12: 7 | R12: 1806 | S12: 0.0065 | T12: 6 | U12: 7 | V12: 1806 | W12: 0.0065 | X12: 4 | Y12: 2 | Z12: 774 | AA12: 0 | AB12: 1.95 | AC12: 774 | AD12: - | AE12: 1806 | AF12: 1806 | AG12: 7 | AH12: 0.0093 | AI12: 108 | AJ12: 1 | AK12: - | AL12: -
A13: 2026-01-01 | B13: 763414867633 | C13: LENNEA法式气质小香风短款外套女2025秋冬加绒显瘦高级感羽绒上衣 | D13: '763414867633 | E13: 主商品 | F13: 20401028 | G13: 当前在线 | H13: - | I13: 148 | J13: 481 | K13: 4.76 | L13: 0.5541 | M13: 5 | N13: 13 | O13: 13 | P13: 5 | Q13: 5 | R13: 1372 | S13: 0.0338 | T13: 5 | U13: 5 | V13: 1372 | W13: 0.0338 | X13: 5 | Y13: 0 | Z13: 0 | AA13: 0 | AB13: 9.27 | AC13: 1134 | AD13: - | AE13: 1372 | AF13: 1372 | AG13: 5 | AH13: 0.037 | AI13: 54 | AJ13: 2 | AK13: - | AL13: -
A14: 2026-01-01 | B14: 843240069717 | C14: LENNEA连帽羽绒服女冬季2025新款面包服超好看设计感小众过冬外套 | D14: '843240069717 | E14: 主商品 | F14: KPAW2023904 | G14: 当前在线 | H14: - | I14: 124 | J14: 318 | K14: 5.05 | L14: 0.3065 | M14: 4 | N14: 5 | O14: 4 | P14: 3 | Q14: 3 | R14: 1191 | S14: 0.0242 | T14: 3 | U14: 3 | V14: 1191 | W14: 0.0242 | X14: 3 | Y14: 0 | Z14: 0 | AA14: 0 | AB14: 9.6 | AC14: 397 | AD14: - | AE14: 1191 | AF14: 1191 | AG14: 3 | AH14: 0.0571 | AI14: 35 | AJ14: 2 | AK14: - | AL14: -
A15: 2026-01-01 | B15: 825738021055 | C15: LENNEA原创高质感白色小香风圆领毛呢上衣肌理感加棉短外套 | D15: '825738021055 | E15: 主商品 | F15: 2024879 | G15: 当前在线 | H15: - | I15: 380 | J15: 675 | K15: 21.53 | L15: 0.7553 | M15: 3 | N15: 11 | O15: 10 | P15: 4 | Q15: 5 | R15: 1190 | S15: 0.0105 | T15: 4 | U15: 5 | V15: 1190 | W15: 0.0105 | X15: 4 | Y15: 0 | Z15: 0 | AA15: 0 | AB15: 3.13 | AC15: 0 | AD15: - | AE15: 1190 | AF15: 1190 | AG15: 5 | AH15: 0 | AI15: 25 | AJ15: 0 | AK15: - | AL15: -
A16: 2026-01-01 | B16: 959252941279 | C16: LENNEA波点花边袖黑色长袖针织开衫女百搭修身打底衫早秋上衣 | D16: '959252941279 | E16: 主商品 | F16: - | G16: 当前在线 | H16: - | I16: 548 | J16: 1623 | K16: 4.95 | L16: 0.5675 | M16: 9 | N16: 60 | O16: 49 | P16: 8 | Q16: 9 | R16: 1332 | S16: 0.0146 | T16: 8 | U16: 8 | V16: 1184 | W16: 0.0146 | X16: 8 | Y16: 0 | Z16: 0 | AA16: 0 | AB16: 2.16 | AC16: 1142 | AD16: - | AE16: 1184 | AF16: 1184 | AG16: 8 | AH16: 0.0247 | AI16: 81 | AJ16: 2 | AK16: - | AL16: -
A17: 2026-01-01 | B17: 847216230061 | C17: LENNEA原创设计感条纹蝴蝶结棉服外套冬季加绒加厚保暖棉衣女 | D17: '847216230061 | E17: 主商品 | F17: 2024911 | G17: 当前在线 | H17: - | I17: 227 | J17: 540 | K17: 5.58 | L17: 0.37 | M17: 6 | N17: 11 | O17: 11 | P17: 3 | Q17: 3 | R17: 783 | S17: 0.0132 | T17: 3 | U17: 3 | V17: 783 | W17: 0.0132 | X17: 3 | Y17: 0 | Z17: 0 | AA17: 0 | AB17: 3.45 | AC17: 783 | AD17: - | AE17: 783 | AF17: 783 | AG17: 3 | AH17: 0 | AI17: 28 | AJ17: 0 | AK17: - | AL17: -
A18: 2026-01-01 | B18: 987920341922 | C18: LENNEA复古毛领连帽卫衣女202秋冬韩系慵懒风高级感拉链加厚外套 | D18: '987920341922 | E18: 主商品 | F18: 2025303 | G18: 当前在线 | H18: - | I18: 230 | J18: 613 | K18: 3.78 | L18: 0.4652 | M18: 6 | N18: 12 | O18: 12 | P18: 2 | Q18: 3 | R18: 774 | S18: 0.0087 | T18: 1 | U18: 2 | V18: 516 | W18: 0.0043 | X18: 1 | Y18: 0 | Z18: 0 | AA18: 0 | AB18: 2.24 | AC18: 258 | AD18: - | AE18: 516 | AF18: 516 | AG18: 2 | AH18: 0 | AI18: 20 | AJ18: 0 | AK18: - | AL18: -
A19: 2026-01-01 | B19: 990762914987 | C19: LENNEA白色收腰羽绒服女90白鸭绒冬季显瘦毛领连帽保暖外套小个子 | D19: '990762914987 | E19: 主商品 | F19: 2025306 | G19: 当前在线 | H19: - | I19: 159 | J19: 450 | K19: 3.94 | L19: 0.195 | M19: 8 | N19: 22 | O19: 22 | P19: 1 | Q19: 1 | R19: 488 | S19: 0.0063 | T19: 1 | U19: 1 | V19: 488 | W19: 0.0063 | X19: 1 | Y19: 0 | Z19: 0 | AA19: 0 | AB19: 3.07 | AC19: 488 | AD19: - | AE19: 488 | AF19: 488 | AG19: 1 | AH19: 0 | AI19: 17 | AJ19: 0 | AK19: - | AL19: -
A20: 2026-01-01 | B20: 970314453475 | C20: LENNEA藏青色毛领外套女秋冬季新款设计感短款修身显瘦夹棉上衣 | D20: '970314453475 | E20: 主商品 | F20: 2025901 | G20: 当前在线 | H20: - | I20: 610 | J20: 1154 | K20: 4.03 | L20: 0.5279 | M20: 9 | N20: 17 | O20: 16 | P20: 2 | Q20: 2 | R20: 456 | S20: 0.0033 | T20: 2 | U20: 2 | V20: 456 | W20: 0.0033 | X20: 2 | Y20: 0 | Z20: 0 | AA20: 0 | AB20: 0.75 | AC20: 683.9 | AD20: - | AE20: 456 | AF20: 456 | AG20: 2 | AH20: 0.0357 | AI20: 28 | AJ20: 1 | AK20: - | AL20: -
A21: 2026-01-01 | B21: 808571688488 | C21: LENNEA原创设计气质垂感直筒毛呢阔腿裤宽松百搭显瘦拖地休闲裤女 | D21: '808571688488 | E21: 主商品 | F21: 2024867 | G21: 当前在线 | H21: - | I21: 18 | J21: 24 | K21: 4.37 | L21: 0.0556 | M21: 0 | N21: 3 | O21: 3 | P21: 2 | Q21: 2 | R21: 370 | S21: 0.1111 | T21: 2 | U21: 2 | V21: 370 | W21: 0.1111 | X21: 2 | Y21: 0 | Z21: 0 | AA21: 0 | AB21: 20.56 | AC21: 185 | AD21: - | AE21: 370 | AF21: 370 | AG21: 2 | AH21: 0 | AI21: 0 | AJ21: 0 | AK21: - | AL21: -
A22: 2026-01-01 | B22: 1008943112755 | C22: LENNEA 费尔岛风大毛领连帽棉服女冬季宽松加厚保暖面包服外套 | D22: '1008943112755 | E22: 主商品 | F22: 2025890-2 | G22: 当前在线 | H22: - | I22: 84 | J22: 131 | K22: 4.04 | L22: 0.369 | M22: 1 | N22: 4 | O22: 4 | P22: 1 | Q22: 1 | R22: 298 | S22: 0.0119 | T22: 1 | U22: 1 | V22: 298 | W22: 0.0119 | X22: 1 | Y22: 0 | Z22: 0 | AA22: 0 | AB22: 3.55 | AC22: 0 | AD22: - | AE22: 298 | AF22: 298 | AG22: 1 | AH22: 0 | AI22: 0 | AJ22: 0 | AK22: - | AL22: -
A23: 2026-01-01 | B23: 825530682410 | C23: LENNEA仿皮草环保韩女托卡毛毛外套立领加厚款秋冬羊羔毛大衣 | D23: '825530682410 | E23: 主商品 | F23: 2024881 | G23: 当前在线 | H23: - | I23: 19 | J23: 37 | K23: 2.54 | L23: 0.3684 | M23: 1 | N23: 0 | O23: 0 | P23: 2 | Q23: 2 | R23: 556 | S23: 0.1053 | T23: 1 | U23: 1 | V23: 278 | W23: 0.0526 | X23: 0 | Y23: 1 | Z23: 278 | AA23: 0 | AB23: 14.63 | AC23: 278 | AD23: - | AE23: 278 | AF23: 278 | AG23: 1 | AH23: 0 | AI23: 2 | AJ23: 0 | AK23: - | AL23: -
A24: 2026-01-01 | B24: 980262719728 | C24: LENNEA复古美拉德棕色毛呢外套短款修身冬季小个子羊羔毛毛上衣 | D24: '980262719728 | E24: 主商品 | F24: 2025987 | G24: 当前在线 | H24: - | I24: 1084 | J24: 1662 | K24: 5.72 | L24: 0.7122 | M24: 12 | N24: 22 | O24: 22 | P24: 1 | Q24: 1 | R24: 278 | S24: 0.0009 | T24: 1 | U24: 1 | V24: 278 | W24: 0.0009 | X24: 1 | Y24: 0 | Z24: 0 | AA24: 0 | AB24: 0.26 | AC24: 0 | AD24: - | AE24: 278 | AF24: 278 | AG24: 1 | AH24: 0 | AI24: 13 | AJ24: 0 | AK24: - | AL24: -
A25: 2026-01-01 | B25: 847170293443 | C25: LENNEA原创短款格子棉服简约立领高级感通勤复古百搭棉袄保暖外套 | D25: '847170293443 | E25: 主商品 | F25: 2024909 | G25: 当前在线 | H25: - | I25: 69 | J25: 118 | K25: 6.09 | L25: 0.1739 | M25: 2 | N25: 5 | O25: 5 | P25: 1 | Q25: 1 | R25: 270 | S25: 0.0145 | T25: 1 | U25: 1 | V25: 270 | W25: 0.0145 | X25: 1 | Y25: 0 | Z25: 0 | AA25: 0 | AB25: 3.91 | AC25: 0 | AD25: - | AE25: 270 | AF25: 270 | AG25: 1 | AH25: 0 | AI25: 8 | AJ25: 0 | AK25: - | AL25: -
A26: 2026-01-01 | B26: 987928549020 | C26: LENNEA连帽毛领棉服宽松简约棉衣冬季短款面包服连帽外套上衣女 | D26: '987928549020 | E26: 主商品 | F26: 2025890 | G26: 当前在线 | H26: - | I26: 222 | J26: 361 | K26: 4.05 | L26: 0.3198 | M26: 2 | N26: 8 | O26: 8 | P26: 1 | Q26: 1 | R26: 270 | S26: 0.0045 | T26: 1 | U26: 1 | V26: 270 | W26: 0.0045 | X26: 1 | Y26: 0 | Z26: 0 | AA26: 0 | AB26: 1.22 | AC26: 0 | AD26: - | AE26: 270 | AF26: 270 | AG26: 1 | AH26: 0.125 | AI26: 8 | AJ26: 1 | AK26: - | AL26: -
A27: 2026-01-01 | B27: 874018241490 | C27: LENNEA原创蓝色小香风春秋新款财阀千金风气质收腰开衫毛呢外套女 | D27: '874018241490 | E27: 主商品 | F27: 2025605 | G27: 当前在线 | H27: - | I27: 47 | J27: 162 | K27: 2.74 | L27: 0.4681 | M27: 2 | N27: 1 | O27: 1 | P27: 1 | Q27: 1 | R27: 261 | S27: 0.0213 | T27: 1 | U27: 1 | V27: 261 | W27: 0.0213 | X27: 1 | Y27: 0 | Z27: 0 | AA27: 0 | AB27: 5.55 | AC27: 261 | AD27: - | AE27: 261 | AF27: 261 | AG27: 1 | AH27: 0 | AI27: 6 | AJ27: 0 | AK27: - | AL27: -
A28: 2026-01-01 | B28: 987173298099 | C28: LENNEA棕色系带麂皮外套女2025秋冬新款皮毛一体高级感修身短上衣 | D28: '987173298099 | E28: 主商品 | F28: 2025999 | G28: 当前在线 | H28: - | I28: 23 | J28: 75 | K28: 4.39 | L28: 0.3043 | M28: 2 | N28: 3 | O28: 3 | P28: 1 | Q28: 1 | R28: 258 | S28: 0.0435 | T28: 1 | U28: 1 | V28: 258 | W28: 0.0435 | X28: 1 | Y28: 0 | Z28: 0 | AA28: 0 | AB28: 11.22 | AC28: 0 | AD28: - | AE28: 258 | AF28: 258 | AG28: 1 | AH28: 0 | AI28: 2 | AJ28: 0 | AK28: - | AL28: -
A29: 2026-01-01 | B29: 972565039550 | C29: LENNEA韩系奶黄色立领羽绒棉服女2025年秋冬新款小个子保暖棉衣 | D29: '972565039550 | E29: 主商品 | F29: 2025897 | G29: 当前在线 | H29: - | I29: 82 | J29: 178 | K29: 7.28 | L29: 0.3659 | M29: 2 | N29: 14 | O29: 12 | P29: 1 | Q29: 1 | R29: 248 | S29: 0.0122 | T29: 1 | U29: 1 | V29: 248 | W29: 0.0122 | X29: 1 | Y29: 0 | Z29: 0 | AA29: 0 | AB29: 3.02 | AC29: 0 | AD29: - | AE29: 248 | AF29: 248 | AG29: 1 | AH29: 0 | AI29: 13 | AJ29: 0 | AK29: - | AL29: -
A30: 2026-01-01 | B30: 1007363114226 | C30: LENNEA 波点毛绒连帽外套女冬大毛领毛球装饰软糯可爱减龄短外套 | D30: '1007363114226 | E30: 主商品 | F30: 2025327 | G30: 当前在线 | H30: - | I30: 104 | J30: 144 | K30: 4.57 | L30: 0.5865 | M30: 1 | N30: 9 | O30: 8 | P30: 2 | Q30: 2 | R30: 496 | S30: 0.0192 | T30: 1 | U30: 1 | V30: 248 | W30: 0.0096 | X30: 1 | Y30: 0 | Z30: 0 | AA30: 0 | AB30: 2.38 | AC30: 0 | AD30: - | AE30: 248 | AF30: 248 | AG30: 1 | AH30: 0 | AI30: 0 | AJ30: 0 | AK30: - | AL30: -
A31: 2026-01-01 | B31: 728037000377 | C31: LENNEA 25/AW 原创秋冬无领女正肩修身短款小香风学院夹克外套 | D31: '728037000377 | E31: 主商品 | F31: - | G31: 当前在线 | H31: - | I31: 86 | J31: 330 | K31: 5.77 | L31: 0.4651 | M31: 3 | N31: 11 | O31: 6 | P31: 2 | Q31: 3 | R31: 593 | S31: 0.0233 | T31: 1 | U31: 1 | V31: 238 | W31: 0.0116 | X31: 1 | Y31: 0 | Z31: 0 | AA31: 0 | AB31: 2.77 | AC31: 117 | AD31: - | AE31: 238 | AF31: 238 | AG31: 1 | AH31: 0 | AI31: 17 | AJ31: 0 | AK31: - | AL31: -
A32: 2026-01-01 | B32: 920335022314 | C32: LENNEA法式拼接连衣裙女夏季新款简约气质收腰显瘦无袖小众裙子 | D32: '920335022314 | E32: 主商品 | F32: 2025837 | G32: 当前在线 | H32: - | I32: 8 | J32: 9 | K32: 5.86 | L32: 0.25 | M32: 0 | N32: 1 | O32: 1 | P32: 1 | Q32: 1 | R32: 236 | S32: 0.125 | T32: 1 | U32: 1 | V32: 236 | W32: 0.125 | X32: 1 | Y32: 0 | Z32: 0 | AA32: 0 | AB32: 29.5 | AC32: 236 | AD32: - | AE32: 236 | AF32: 236 | AG32: 1 | AH32: 0 | AI32: 0 | AJ32: 0 | AK32: - | AL32: -
A33: 2026-01-01 | B33: 980263183781 | C33: LENNEA撞色条纹连帽大毛领羊羔毛外套女冬季宽松保暖圈圈毛棉衣 | D33: '980263183781 | E33: 主商品 | F33: 2025990 | G33: 已下架 | H33: - | I33: 153 | J33: 367 | K33: 2.87 | L33: 0.451 | M33: 1 | N33: 5 | O33: 5 | P33: 1 | Q33: 1 | R33: 228 | S33: 0.0065 | T33: 1 | U33: 1 | V33: 228 | W33: 0.0065 | X33: 1 | Y33: 0 | Z33: 0 | AA33: 0 | AB33: 1.49 | AC33: 228 | AD33: - | AE33: 228 | AF33: 228 | AG33: 1 | AH33: 0 | AI33: 20 | AJ33: 0 | AK33: - | AL33: -
A34: 2026-01-01 | B34: 905004041827 | C34: LENNEA原创蕾丝荡领短袖t恤女夏季纯欲设计感斜肩别致韩系上衣 | D34: '905004041827 | E34: 主商品 | F34: 2025932 | G34: 当前在线 | H34: - | I34: 37 | J34: 88 | K34: 3.71 | L34: 0.2973 | M34: 2 | N34: 5 | O34: 4 | P34: 1 | Q34: 1 | R34: 227 | S34: 0.027 | T34: 1 | U34: 1 | V34: 227 | W34: 0.027 | X34: 0 | Y34: 1 | Z34: 227 | AA34: 0 | AB34: 6.14 | AC34: 0 | AD34: - | AE34: 227 | AF34: 227 | AG34: 1 | AH34: 0 | AI34: 2 | AJ34: 0 | AK34: - | AL34: -
A35: 2026-01-01 | B35: 858672318475 | C35: LENNEA蝴蝶结格子拼接设计感宽松直筒拖地高腰牛仔裤女显瘦长裤 | D35: '858672318475 | E35: 主商品 | F35: 2024913 | G35: 当前在线 | H35: - | I35: 76 | J35: 172 | K35: 5.12 | L35: 0.2763 | M35: 4 | N35: 7 | O35: 7 | P35: 1 | Q35: 2 | R35: 370 | S35: 0.0132 | T35: 1 | U35: 1 | V35: 185 | W35: 0.0132 | X35: 1 | Y35: 0 | Z35: 0 | AA35: 0 | AB35: 2.43 | AC35: 370 | AD35: - | AE35: 185 | AF35: 185 | AG35: 1 | AH35: 0 | AI35: 10 | AJ35: 0 | AK35: - | AL35: -
A36: 2026-01-01 | B36: 847172837136 | C36: LENNEA宽松休闲毛呢裤女高腰百搭显瘦阔腿裤直筒简约拖地长裤 | D36: '847172837136 | E36: 主商品 | F36: 2024910 | G36: 当前在线 | H36: - | I36: 22 | J36: 40 | K36: 5.4 | L36: 0.4545 | M36: 0 | N36: 2 | O36: 2 | P36: 1 | Q36: 1 | R36: 170 | S36: 0.0455 | T36: 1 | U36: 1 | V36: 170 | W36: 0.0455 | X36: 1 | Y36: 0 | Z36: 0 | AA36: 0 | AB36: 7.73 | AC36: 0 | AD36: - | AE36: 170 | AF36: 170 | AG36: 1 | AH36: 0 | AI36: 5 | AJ36: 0 | AK36: - | AL36: -
A37: 2026-01-01 | B37: 988564242366 | C37: 【秋冬合集】LENNEA双十一惊喜福袋粉丝福利抢购秋冬款上衣外套 | D37: '988564242366 | E37: 主商品 | F37: - | G37: 当前在线 | H37: - | I37: 156 | J37: 363 | K37: 9.49 | L37: 0.3333 | M37: 2 | N37: 10 | O37: 10 | P37: 1 | Q37: 1 | R37: 127 | S37: 0.0064 | T37: 1 | U37: 1 | V37: 127 | W37: 0.0064 | X37: 0 | Y37: 1 | Z37: 127 | AA37: 0 | AB37: 0.81 | AC37: 412 | AD37: - | AE37: 127 | AF37: 127 | AG37: 1 | AH37: 0 | AI37: 39 | AJ37: 0 | AK37: - | AL37: -
A38: 2026-01-01 | B38: 926919925240 | C38: LENNEA粉色蓬蓬花苞半身裙女夏季新款设计感高腰显瘦a字芭蕾裤裙 | D38: '926919925240 | E38: 主商品 | F38: 2025999 | G38: 当前在线 | H38: - | I38: 23 | J38: 40 | K38: 5.27 | L38: 0.4783 | M38: 0 | N38: 2 | O38: 2 | P38: 1 | Q38: 1 | R38: 125 | S38: 0.0435 | T38: 1 | U38: 1 | V38: 125 | W38: 0.0435 | X38: 1 | Y38: 0 | Z38: 0 | AA38: 0 | AB38: 5.43 | AC38: 0 | AD38: - | AE38: 125 | AF38: 125 | AG38: 1 | AH38: 0.0769 | AI38: 13 | AJ38: 1 | AK38: - | AL38: -
A39: 2026-01-01 | B39: 920848709238 | C39: LENNEA甜美少女感娃娃领衬衫女白色短袖衬衣纯色显瘦休闲薄款上衣 | D39: '920848709238 | E39: 主商品 | F39: 2025954 | G39: 当前在线 | H39: - | I39: 14 | J39: 22 | K39: 4.11 | L39: 0.5 | M39: 1 | N39: 1 | O39: 1 | P39: 1 | Q39: 1 | R39: 114 | S39: 0.0714 | T39: 1 | U39: 1 | V39: 114 | W39: 0.0714 | X39: 1 | Y39: 0 | Z39: 0 | AA39: 0 | AB39: 8.14 | AC39: 114 | AD39: - | AE39: 114 | AF39: 114 | AG39: 1 | AH39: 0 | AI39: 1 | AJ39: 0 | AK39: - | AL39: -
A40: 2026-01-01 | B40: 728030472469 | C40: LENNEA 23/AW 原创秋冬女长袖通勤宽松宽松高腰学生设计条纹衬衫 | D40: '728030472469 | E40: 主商品 | F40: - | G40: 当前在线 | H40: - | I40: 14 | J40: 25 | K40: 5.54 | L40: 0.3571 | M40: 2 | N40: 0 | O40: 0 | P40: 0 | Q40: 0 | R40: 0 | S40: 0 | T40: 0 | U40: 0 | V40: 0 | W40: 0 | X40: 0 | Y40: 0 | Z40: 0 | AA40: 0 | AB40: 0 | AC40: 0 | AD40: - | AE40: 0 | AF40: 0 | AG40: 0 | AH40: 0 | AI40: 2 | AJ40: 0 | AK40: - | AL40: -
...

Sheet 指标统计
A1: 序号 | B1: 一级分类 | C1: 表 | D1: 列名 | E1: 字段类型 | F1: 数据来源 | G1: 备注
A2: 1 | B2: 数据管理 | C2: 博主库 | D2: 联系人 | E2: 源数据 | F2: 人工 | G2: -
A3: 2 | B3: 数据管理 | C3: 博主库 | D3: 小红书昵称 | E3: 源数据 | F3: 人工 | G3: -
A4: 3 | B4: 数据管理 | C4: 博主库 | D4: 小红书ID | E4: 源数据 | F4: 人工 | G4: -
A5: 4 | B5: 数据管理 | C5: 博主库 | D5: 邮箱(联系上的可不填) | E5: 源数据 | F5: 人工 | G5: -
A6: 5 | B6: 数据管理 | C6: 博主库 | D6: 微信号 | E6: 源数据 | F6: 人工 | G6: -
A7: 6 | B7: 数据管理 | C7: 博主库 | D7: 报价 | E7: 源数据 | F7: 人工 | G7: -
A8: 7 | B8: 数据管理 | C8: 博主库 | D8: 粉丝量 | E8: 爬虫 | F8: 影刀 | G8: 每天增量更新到固定文件夹
A9: 8 | B9: 数据管理 | C9: 博主库 | D9: 3篇阅读量 | E9: 爬虫 | F9: 影刀 | G9: 每天增量更新到固定文件夹
A10: 9 | B10: 数据管理 | C10: 博主库 | D10: 3篇点赞数 | E10: 爬虫 | F10: 影刀 | G10: 每天增量更新到固定文件夹
A11: 10 | B11: 数据管理 | C11: 博主库 | D11: 3篇收藏数 | E11: 爬虫 | F11: 影刀 | G11: 每天增量更新到固定文件夹
A12: 11 | B12: 数据管理 | C12: 博主库 | D12: 3篇评论数 | E12: 爬虫 | F12: 影刀 | G12: 每天增量更新到固定文件夹
A13: 12 | B13: 数据管理 | C13: 博主库 | D13: 7篇阅读量 | E13: 爬虫 | F13: 影刀 | G13: 每天增量更新到固定文件夹
... A227: 226 | B227: 财务管理 | C227: 余额核对 | D227: 备注 | E227: 源数据 | F227: 人工 | G227: -

Sheet 余额核对
A1: 日期 | B1: 充值收入 | C1: 推广支出 | D1: 刷/拍单支出 | E1: 余额 | F1: 余额截图 | G1: 备注
A2: 45930 | B2: 4272.02 | C2: 4077 | D2: 2558.37 | E2: 195.02
A3: 45931 | B3: 0 | C3: 500 | D3: 2558.37 | E3: -500 | G3: -200
A4: 45939 | B4: 36195.02 | C4: 26943.06 | D4: 2558.37 | E4: 9251.96

Sheet 拍单
A1: 销售类型 | B1: 拍单日期 | C1: 订单号 | D1: 博主ID/微信ID | E1: 款式 | F1: 款号 | G1: 金额 | H1: 付款金额 | I1: 付款日期
A2: 拍单 | B2: 46029 | C2: 3161196303779557591 | D2: 小红书：Zzz- | E2: 波点套 费尔岛毛衣 蕾丝防晒衬衫 一字肩针织连衣裙 | F2: 2025933 | G2: 298 | H2: 298 | I2: 46035
A3: 刷单 | B3: 46032 | C3: 3059182310768877461 | D3: 155的瑶瑶阿 | E3: 波点套 双排扣小香 一字肩针织连衣裙 蕾丝防晒衬衫 | F3: 2025933 | G3: 298 | H3: 298 | I3: 46036
A4: 刷单 | B4: 46032 | C4: 4877572609413972718 | D4: 丰腴幼软 | E4: 波点套 一字肩针织连衣裙 拼接针织套 | F4: 2025933 | G4: 298 | H4: 298 | I4: 46037
A5: 刷单 | B5: 46057 | C5: 3226009117153132788 | D5: -coin88 | E5: 波点套 费尔岛毛衣 蕾丝防晒衬衫 一字肩针织连衣裙 | F5: 2025933 | G5: 298 | H5: 298 | I5: 46038
A6: 刷单 | B6: 46057 | C6: 3226185192668351880 | D6: 沙琪奶芙 | E6: 波点套 双排扣小香 一字肩针织连衣裙 蕾丝防晒衬衫 | F6: 2025933 | G6: 298 | H6: 298 | I6: 46039
A7: 刷单 | B7: 46057 | C7: 3226185192668351880 | D7: D子别买了 | E7: 波点套 一字肩针织连衣裙 拼接针织套 | F7: 2025933 | G7: 298 | H7: 298 | I7: 46040
A8: 刷单 | B8: 46111 | C8: 2701784750043047564 | D8: 淡淡的绿 | E8: 波点套 费尔岛毛衣 蕾丝防晒衬衫 一字肩针织连衣裙 | F8: 2025933 | G8: 298 | H8: 298 | I8: 46041
A9: 刷单 | B9: 46111 | C9: 2701775281166026593 | D9: HTG | E9: 波点套 双排扣小香 一字肩针织连衣裙 蕾丝防晒衬衫 | F9: 2025933 | G9: 298 | H9: 298 | I9: 46042
A10: 刷单 | B10: 46111 | C10: 2701789717049023590 | D10: 果仁儿曦 | E10: 波点套 一字肩针织连衣裙 拼接针织套 | F10: 2025933 | G10: 298 | H10: 298 | I10: 46043
A11: 刷单 | B11: 46111 | C11: 2701786263037039088 | D11: 邪恶的00 | E11: 波点套 费尔岛毛衣 蕾丝防晒衬衫 一字肩针织连衣裙 | F11: 2025933 | G11: 298 | H11: 298 | I11: 46044
A12: 刷单 | B12: 46111 | C12: 4502207631032004708 | D12: 睡觉了 | E12: 波点套 双排扣小香 一字肩针织连衣裙 蕾丝防晒衬衫 | F12: 2025933 | G12: 298 | H12: 298 | I12: 46045
A13: 刷单 | B13: 46111 | C13: 2701774526065001370 | D13: 好甜 | E13: 波点套 一字肩针织连衣裙 拼接针织套 | F13: 2025933 | G13: 298 | H13: 298 | I13: 46046
... A48: 刷单 | B48: 46129 | C48: 4502264871185007827 | D48: quqookicu | E48: 波点套 双排扣小香 一字肩针织连衣裙 蕾丝防晒衬衫 | F48: 2025933 | G48: 298 | H48: 298 | I48: 46081

Sheet 单品站内推广数据
A1: 日期 | B1: 主体ID | C1: 主体类型 | D1: 主体名称 | E1: 展现量 | F1: 点击量 | G1: 花费 | H1: 点击率 | I1: 平均点击花费 | J1: 千次展现花费 | K1: 总预售成交金额 | L1: 总预售成交笔数 | M1: 直接预售成交金额 | N1: 直接预售成交笔数 | O1: 间接预售成交金额 | P1: 间接预售成交笔数 | Q1: 直接成交金额 | R1: 间接成交金额 | S1: 总成交金额 | T1: 总成交笔数 | U1: 直接成交笔数 | V1: 间接成交笔数 | W1: 点击转化率 | X1: 投入产出比 | Y1: 含预售投产比 | Z1: 总成交成本 | AA1: 总购物车数 | AB1: 直接购物车数 | AC1: 间接购物车数 | AD1: 加购率 | AE1: 收藏宝贝数 | AF1: 收藏店铺数 | AG1: 店铺收藏成本 | AH1: 总收藏加购数 | AI1: 总收藏加购成本 | AJ1: 宝贝收藏加购数 | AK1: 宝贝收藏加购成本 | AL1: 总收藏数 | AM1: 宝贝收藏成本 | AN1: 宝贝收藏率 | AO1: 加购成本 | AP1: 拍下订单笔数 | AQ1: 拍下订单金额 | AR1: 直接收藏宝贝数 | AS1: 间接收藏宝贝数 | AT1: 优惠券领取量 | AU1: 购物金充值笔数 | AV1: 购物金充值金额 | AW1: 旺旺咨询量 | AX1: 引导访问量 | AY1: 引导访问人数 | AZ1: 引导访问潜客数 | BA1: 引导访问潜客占比 | BB1: 入会率 | BC1: 入会量 | BD1: 引导访问率 | BE1: 深度访问量 | BF1: 平均访问页面数 | BG1: 成交新客数 | BH1: 成交新客占比 | BI1: 会员首购人数 | BJ1: 会员成交金额 | BK1: 会员成交笔数 | BL1: 成交人数 | BM1: 人均成交笔数 | BN1: 人均成交金额 | BO1: 自然流量转化金额 | BP1: 自然流量曝光量 | BQ1: 宝贝优惠券抵扣金额 | BR1: 宝贝优惠券撬动总成交 | BS1: 宝贝优惠券撬动直接成交 | BT1: 宝贝优惠券撬动点击
A2: 46104 | B2: 1027636684171 | C2: 商品 | D2: LENNEA法式小个子设计感减龄蓝色连衣裙子女夏季无袖背心花苞短裙 | E2: 3556 | F2: 172 | G2: 45.08 | H2: 0.04837 | I2: 0.26 | J2: 12.68 | K2: 0 | L2: 0 | M2: 0 | N2: 0 | O2: 0 | P2: 0 | Q2: 352 | R2: 292 | S2: 644 | T2: 4 | U2: 2 | V2: 2 | W2: 0.02326 | X2: 14.29 | Y2: 14.29 | Z2: 11.27 | AA2: 13 | AB2: 11 | AC2: 2 | AD2: 0.07558 | AE2: 3 | AF2: 0 | AH2: 16 | AI2: 2.82 | AJ2: 16 | AK2: 2.82 | AL2: 3 | AM2: 15.03 | AN2: 0.01744 | AO2: 3.47 | AP2: 4 | AQ2: 761 | AR2: 3 | AS2: 0 | AT2: 0 | AU2: 0 | AV2: 0 | AW2: 1 | AX2: 338 | AY2: 163 | AZ2: 137 | BA2: 0.84049 | BB2: 0 | BC2: 0 | BD2: 0.09505 | BE2: 150 | BF2: 2 | BG2: 3 | BH2: 1 | BI2: 0 | BJ2: 0 | BK2: 0 | BL2: 3 | BM2: 1 | BN2: 214.67 | BO2: 0 | BP2: 0 | BQ2: 0 | BR2: 0 | BS2: 0 | BT2: 0
A3: 46104 | B3: 1024058244420 | C3: 商品 | D3: LENNEA法式油画网纱连衣裙夏季原创设计收腰圆领无袖背心碎花短裙 | E3: 390 | F3: 27 | G3: 2.83 | H3: 0.06923 | I3: 0.1 | J3: 7.26 | K3: 0 | L3: 0 | M3: 0 | N3: 0 | O3: 0 | P3: 0 | Q3: 0 | R3: 0 | S3: 0 | T3: 0 | U3: 0 | V3: 0 | W3: 0 | X3: 0 | Y3: 0 | AA3: 1 | AB3: 1 | AC3: 0 | AD3: 0.03704 | AE3: 1 | AF3: 1 | AG3: 2.83 | AH3: 3 | AI3: 0.94 | AJ3: 2 | AK3: 1.42 | AL3: 2 | AM3: 2.83 | AN3: 0.03704 | AO3: 2.83 | AP3: 0 | AQ3: 0 | AR3: 0 | AS3: 1 | AT3: 0 | AU3: 0 | AV3: 0 | AW3: 0 | AX3: 42 | AY3: 26 | AZ3: 22 | BA3: 0.84615 | BB3: 0 | BC3: 0 | BD3: 0.10769 | BE3: 15 | BF3: 2 | BG3: 0 | BI3: 0 | BJ3: 0 | BK3: 0 | BL3: 0 | BO3: 0 | BP3: 0 | BQ3: 0 | BR3: 0 | BS3: 0 | BT3: 0
A4: 46104 | B4: 1024056756230 | C4: 商品 | D4: LENNEA粉色碎花雪纺鱼尾裙夏季女高腰显瘦半身裙小个子短裙包臀裙 | E4: 114 | F4: 15 | G4: 1.38 | H4: 0.13158 | I4: 0.09 | J4: 12.11 | K4: 0 | L4: 0 | M4: 0 | N4: 0 | O4: 0 | P4: 0 | Q4: 0 | R4: 0 | S4: 0 | T4: 0 | U4: 0 | V4: 0 | W4: 0 | X4: 0 | Y4: 0 | AA4: 1 | AB4: 1 | AC4: 0 | AD4: 0.06667 | AE4: 0 | AF4: 0 | AH4: 1 | AI4: 1.38 | AJ4: 1 | AK4: 1.38 | AL4: 0 | AN4: 0 | AO4: 1.38 | AP4: 0 | AQ4: 0 | AR4: 0 | AS4: 0 | AT4: 0 | AU4: 0 | AV4: 0 | AW4: 0 | AX4: 22 | AY4: 14 | AZ4: 13 | BA4: 0.92857 | BB4: 0 | BC4: 0 | BD4: 0.19298 | BE4: 7 | BF4: 2 | BG4: 0 | BI4: 0 | BJ4: 0 | BK4: 0 | BL4: 0 | BO4: 0 | BP4: 0 | BQ4: 0 | BR4: 0 | BS4: 0 | BT4: 0
A5: 46104 | B5: 1024056572913 | C5: 商品 | D5: LENNEA假两件坎肩长袖针织衫女早春修身甜美内搭抹胸打底辣妹上衣 | E5: 279 | F5: 28 | G5: 12.47 | H5: 0.10036 | I5: 0.45 | J5: 44.7 | K5: 0 | L5: 0 | M5: 0 | N5: 0 | O5: 0 | P5: 0 | Q5: 0 | R5: 0 | S5: 0 | T5: 0 | U5: 0 | V5: 0 | W5: 0 | X5: 0 | Y5: 0 | AA5: 13 | AB5: 0 | AC5: 13 | AD5: 0.46429 | AE5: 5 | AF5: 1 | AG5: 12.47 | AH5: 19 | AI5: 0.66 | AJ5: 18 | AK5: 0.69 | AL5: 6 | AM5: 2.49 | AN5: 0.17857 | AO5: 0.96 | AP5: 0 | AQ5: 0 | AR5: 0 | AS5: 5 | AT5: 0 | AU5: 0 | AV5: 0 | AW5: 1 | AX5: 223 | AY5: 28 | AZ5: 22 | BA5: 0.78571 | BB5: 0 | BC5: 0 | BD5: 0.79928 | BE5: 195 | BF5: 8 | BG5: 0 | BI5: 0 | BJ5: 0 | BK5: 0 | BL5: 0 | BO5: 0 | BP5: 0 | BQ5: 0 | BR5: 0 | BS5: 0 | BT5: 0
A6: 46104 | B6: 1023269465985 | C6: 商品 | D6: LENNEA天丝荷叶边沙滩海边度假风吊带上衣夏季小个子连衣裙两件套 | E6: 644 | F6: 49 | G6: 5.13 | H6: 0.07609 | I6: 0.1 | J6: 7.97 | K6: 0 | L6: 0 | M6: 0 | N6: 0 | O6: 0 | P6: 0 | Q6: 0 | R6: 0 | S6: 0 | T6: 0 | U6: 0 | V6: 0 | W6: 0 | X6: 0 | Y6: 0 | AA6: 2 | AB6: 2 | AC6: 0 | AD6: 0.04082 | AE6: 0 | AF6: 0 | AH6: 2 | AI6: 2.57 | AJ6: 2 | AK6: 2.57 | AL6: 0 | AN6: 0 | AO6: 2.57 | AP6: 0 | AQ6: 0 | AR6: 0 | AS6: 0 | AT6: 0 | AU6: 0 | AV6: 0 | AW6: 0 | AX6: 72 | AY6: 48 | AZ6: 41 | BA6: 0.85417 | BB6: 0 | BC6: 0 | BD6: 0.1118 | BE6: 22 | BF6: 2 | BG6: 0 | BI6: 0 | BJ6: 0 | BK6: 0 | BL6: 0 | BO6: 0 | BP6: 0 | BQ6: 0 | BR6: 0 | BS6: 0 | BT6: 0
A7: 46104 | B7: 1022374874271 | C7: 商品 | D7: LENNEA初恋小白裙春夏季甜美减龄娃娃领短袖连衣裙小个子宽松短裙 | E7: 122 | F7: 6 | G7: 0.99 | H7: 0.04918 | I7: 0.17 | J7: 8.11 | K7: 0 | L7: 0 | M7: 0 | N7: 0 | O7: 0 | P7: 0 | Q7: 0 | R7: 0 | S7: 0 | T7: 0 | U7: 0 | V7: 0 | W7: 0 | X7: 0 | Y7: 0 | AA7: 0 | AB7: 0 | AC7: 0 | AD7: 0 | AE7: 0 | AF7: 0 | AH7: 0 | AJ7: 0 | AL7: 0 | AN7: 0 | AP7: 0 | AQ7: 0 | AR7: 0 | AS7: 0 | AT7: 0 | AU7: 0 | AV7: 0 | AW7: 0 | AX7: 20 | AY7: 7 | AZ7: 5 | BA7: 0.71429 | BB7: 0 | BC7: 0 | BD7: 0.16393 | BE7: 10 | BF7: 3 | BG7: 0 | BI7: 0 | BJ7: 0 | BK7: 0 | BL7: 0 | BO7: 0 | BP7: 0 | BQ7: 0 | BR7: 0 | BS7: 0 | BT7: 0
A8: 46104 | B8: 1018640025168 | C8: 商品 | D8: LENNEA黑色气质收腰娃娃领短袖连衣裙夏季小个子高级感小黑裙短裙 | E8: 484 | F8: 19 | G8: 6.45 | H8: 0.03926 | I8: 0.34 | J8: 13.33 | K8: 0 | L8: 0 | M8: 0 | N8: 0 | O8: 0 | P8: 0 | Q8: 0 | R8: 0 | S8: 0 | T8: 0 | U8: 0 | V8: 0 | W8: 0 | X8: 0 | Y8: 0 | AA8: 1 | AB8: 1 | AC8: 0 | AD8: 0.05263 | AE8: 0 | AF8: 0 | AH8: 1 | AI8: 6.45 | AJ8: 1 | AK8: 6.45 | AL8: 0 | AN8: 0 | AO8: 6.45 | AP8: 0 | AQ8: 0 | AR8: 0 | AS8: 0 | AT8: 0 | AU8: 0 | AV8: 0 | AW8: 0 | AX8: 32 | AY8: 18 | AZ8: 14 | BA8: 0.77778 | BB8: 0 | BC8: 0 | BD8: 0.06612 | BE8: 14 | BF8: 2 | BG8: 0 | BI8: 0 | BJ8: 0 | BK8: 0 | BL8: 0 | BO8: 0 | BP8: 0 | BQ8: 0 | BR8: 0 | BS8: 0 | BT8: 0
A9: 46104 | B9: 1017763274224 | C9: 商品 | D9: LENNEA芭蕾风蓝色收腰连衣裙夏季无袖蓬蓬裙公主裙小个子千金短裙 | E9: 6389 | F9: 549 | G9: 215.36 | H9: 0.08593 | I9: 0.39 | J9: 33.71 | K9: 0 | L9: 0 | M9: 0 | N9: 0 | O9: 0 | P9: 0 | Q9: 0 | R9: 1297 | S9: 1297 | T9: 9 | U9: 0 | V9: 9 | W9: 0.01639 | X9: 6.02 | Y9: 6.02 | Z9: 23.93 | AA9: 177 | AB9: 5 | AC9: 172 | AD9: 0.3224 | AE9: 31 | AF9: 15 | AG9: 14.36 | AH9: 223 | AI9: 0.97 | AJ9: 208 | AK9: 1.04 | AL9: 46 | AM9: 6.95 | AN9: 0.05647 | AO9: 1.22 | AP9: 10 | AQ9: 1740 | AR9: 4 | AS9: 27 | AT9: 0 | AU9: 0 | AV9: 0 | AW9: 12 | AX9: 2824 | AY9: 506 | AZ9: 448 | BA9: 0.88538 | BB9: 0 | BC9: 0 | BD9: 0.44201 | BE9: 2253 | BF9: 6 | BG9: 6 | BH9: 1 | BI9: 0 | BJ9: 0 | BK9: 0 | BL9: 6 | BM9: 2 | BN9: 216.17 | BO9: 0 | BP9: 0 | BQ9: 0 | BR9: 0 | BS9: 0 | BT9: 0
A10: 46104 | B10: 1017116707008 | C10: 商品 | D10: LENNEA波点花边袖黑色短袖针织T恤女圆领修身打底衫早春小众上衣 | E10: 6345 | F10: 361 | G10: 116.21 | H10: 0.0569 | I10: 0.32 | J10: 18.32 | K10: 0 | L10: 0 | M10: 0 | N10: 0 | O10: 0 | P10: 0 | Q10: 282 | R10: 588 | S10: 870 | T10: 6 | U10: 2 | V10: 4 | W10: 0.01662 | X10: 7.49 | Y10: 7.49 | Z10: 19.37 | AA10: 51 | AB10: 36 | AC10: 15 | AD10: 0.14127 | AE10: 15 | AF10: 5 | AG10: 23.24 | AH10: 71 | AI10: 1.64 | AJ10: 66 | AK10: 1.76 | AL10: 20 | AM10: 7.75 | AN10: 0.04155 | AO10: 2.28 | AP10: 6 | AQ10: 1028 | AR10: 6 | AS10: 9 | AT10: 0 | AU10: 0 | AV10: 0 | AW10: 8 | AX10: 1050 | AY10: 341 | AZ10: 219 | BA10: 0.64223 | BB10: 0 | BC10: 0 | BD10: 0.16548 | BE10: 649 | BF10: 3 | BG10: 5 | BH10: 1 | BI10: 0 | BJ10: 0 | BK10: 0 | BL10: 5 | BM10: 1 | BN10: 174 | BO10: 0 | BP10: 0 | BQ10: 0 | BR10: 0 | BS10: 0 | BT10: 0
A11: 46104 | B11: 1008947108996 | C11: 商品 | D11: LENNEA 学院风娃娃领纽扣短外套女韩系春季长袖开衫白色半裙套装 | E11: 5998 | F11: 319 | G11: 45.54 | H11: 0.05318 | I11: 0.14 | J11: 7.59 | K11: 0 | L11: 0 | M11: 0 | N11: 0 | O11: 0 | P11: 0 | Q11: 187 | R11: 144 | S11: 331 | T11: 2 | U11: 1 | V11: 1 | W11: 0.00627 | X11: 7.27 | Y11: 7.27 | Z11: 22.77 | AA11: 12 | AB11: 4 | AC11: 8 | AD11: 0.03762 | AE11: 1 | AF11: 3 | AG11: 15.18 | AH11: 16 | AI11: 2.85 | AJ11: 13 | AK11: 3.5 | AL11: 4 | AM11: 45.54 | AN11: 0.00313 | AO11: 3.8 | AP11: 2 | AQ11: 391 | AR11: 0 | AS11: 1 | AT11: 0 | AU11: 0 | AV11: 0 | AW11: 2 | AX11: 731 | AY11: 305 | AZ11: 232 | BA11: 0.76066 | BB11: 0 | BC11: 0 | BD11: 0.12187 | BE11: 372 | BF11: 2 | BG11: 2 | BH11: 1 | BI11: 0 | BJ11: 0 | BK11: 0 | BL11: 2 | BM11: 1 | BN11: 165.5 | BO11: 0 | BP11: 0 | BQ11: 0 | BR11: 0 | BS11: 0 | BT11: 0
A12: 46104 | B12: 1008945688714 | C12: 商品 | D12: LENNEA 春季少女风蕾丝拼接衬衫女长袖宽松防晒薄款外套休闲百搭 | E12: 8727 | F12: 577 | G12: 90.42 | H12: 0.06612 | I12: 0.16 | J12: 10.36 | K12: 0 | L12: 0 | M12: 0 | N12: 0 | O12: 0 | P12: 0 | Q12: 447 | R12: 0 | S12: 447 | T12: 3 | U12: 3 | V12: 0 | W12: 0.0052 | X12: 4.94 | Y12: 4.94 | Z12: 30.14 | AA12: 31 | AB12: 28 | AC12: 3 | AD12: 0.05373 | AE12: 7 | AF12: 1 | AG12: 90.42 | AH12: 39 | AI12: 2.32 | AJ12: 38 | AK12: 2.38 | AL12: 8 | AM12: 12.92 | AN12: 0.01213 | AO12: 2.92 | AP12: 3 | AQ12: 528 | AR12: 7 | AS12: 0 | AT12: 0 | AU12: 0 | AV12: 0 | AW12: 1 | AX12: 1175 | AY12: 560 | AZ12: 424 | BA12: 0.75714 | BB12: 0 | BC12: 0 | BD12: 0.13464 | BE12: 573 | BF12: 2 | BG12: 3 | BH12: 1 | BI12: 0 | BJ12: 0 | BK12: 0 | BL12: 3 | BM12: 1 | BN12: 149 | BO12: 0 | BP12: 0 | BQ12: 0 | BR12: 0 | BS12: 0 | BT12: 0
A13: 46104 | B13: 1008197333492 | C13: 商品 | D13: LENNEA 2026年春季千金风一字肩针织连衣裙女蓝色系腰带短裙子 | E13: 158 | F13: 12 | G13: 3.22 | H13: 0.07595 | I13: 0.27 | J13: 20.38 | K13: 0 | L13: 0 | M13: 0 | N13: 0 | O13: 0 | P13: 0 | Q13: 0 | R13: 0 | S13: 0 | T13: 0 | U13: 0 | V13: 0 | W13: 0 | X13: 0 | Y13: 0 | AA13: 2 | AB13: 0 | AC13: 2 | AD13: 0.16667 | AE13: 3 | AF13: 1 | AG13: 3.22 | AH13: 6 | AI13: 0.54 | AJ13: 5 | AK13: 0.64 | AL13: 4 | AM13: 1.07 | AN13: 0.25 | AO13: 1.61 | AP13: 0 | AQ13: 0 | AR13: 0 | AS13: 3 | AT13: 0 | AU13: 0 | AV13: 0 | AW13: 0 | AX13: 52 | AY13: 12 | AZ13: 12 | BA13: 1 | BB13: 0 | BC13: 0 | BD13: 0.32911 | BE13: 40 | BF13: 4 | BG13: 0 | BI13: 0 | BJ13: 0 | BK13: 0 | BL13: 0 | BO13: 0 | BP13: 0 | BQ13: 0 | BR13: 0 | BS13: 0 | BT13: 0
A14: 46104 | B14: 1008191325407 | C14: 商品 | D14: LENNEA学院风高领麻花毛衣女春秋宽松不对称斗篷针织衫慵懒风上衣 | E14: 319 | F14: 20 | G14: 2.95 | H14: 0.0627 | I14: 0.15 | J14: 9.25 | K14: 0 | L14: 0 | M14: 0 | N14: 0 | O14: 0 | P14: 0 | Q14: 189 | R14: 0 | S14: 189 | T14: 1 | U14: 1 | V14: 0 | W14: 0.05 | X14: 64.07 | Y14: 64.07 | Z14: 2.95 | AA14: 3 | AB14: 1 | AC14: 2 | AD14: 0.15 | AE14: 0 | AF14: 0 | AH14: 3 | AI14: 0.98 | AJ14: 3 | AK14: 0.98 | AL14: 0 | AN14: 0 | AO14: 0.98 | AP14: 1 | AQ14: 223 | AR14: 0 | AS14: 0 | AT14: 0 | AU14: 0 | AV14: 0 | AW14: 1 | AX14: 40 | AY14: 19 | AZ14: 18 | BA14: 0.94737 | BB14: 0 | BC14: 0 | BD14: 0.12539 | BE14: 18 | BF14: 2 | BG14: 1 | BH14: 1 | BI14: 0 | BJ14: 0 | BK14: 0 | BL14: 1 | BM14: 1 | BN14: 189 | BO14: 0 | BP14: 0 | BQ14: 0 | BR14: 0 | BS14: 0 | BT14: 0
A15: 46104 | B15: 1007371530025 | C15: 商品 | D15: LENNEA 复古风立领短款风衣女春季双排扣设计感长袖休闲外套宽松 | E15: 9425 | F15: 721 | G15: 100.85 | H15: 0.0765 | I15: 0.14 | J15: 10.7 | K15: 0 | L15: 0 | M15: 0 | N15: 0 | O15: 0 | P15: 0 | Q15: 1485 | R15: 0 | S15: 1485 | T15: 4 | U15: 4 | V15: 0 | W15: 0.00555 | X15: 14.72 | Y15: 14.72 | Z15: 25.21 | AA15: 20 | AB15: 19 | AC15: 1 | AD15: 0.02774 | AE15: 2 | AF15: 0 | AH15: 22 | AI15: 4.58 | AJ15: 22 | AK15: 4.58 | AL15: 2 | AM15: 50.43 | AN15: 0.00277 | AO15: 5.04 | AP15: 5 | AQ15: 2100 | AR15: 2 | AS15: 0 | AT15: 0 | AU15: 0 | AV15: 0 | AW15: 0 | AX15: 1397 | AY15: 701 | AZ15: 630 | BA15: 0.89872 | BB15: 0 | BC15: 0 | BD15: 0.14822 | BE15: 643 | BF15: 2 | BG15: 4 | BH15: 1 | BI15: 0 | BJ15: 0 | BK15: 0 | BL15: 4 | BM15: 1 | BN15: 371.25 | BO15: 0 | BP15: 0 | BQ15: 0 | BR15: 0 | BS15: 0 | BT15: 0
A16: 46104 | B16: 1006744639564 | C16: 商品 | D16: LENNEA 费尔岛风连帽拉链针织开衫女春秋冬宽松学院风毛衣外套 | E16: 39 | F16: 5 | G16: 0.73 | H16: 0.12821 | I16: 0.15 | J16: 18.72 | K16: 0 | L16: 0 | M16: 0 | N16: 0 | O16: 0 | P16: 0 | Q16: 0 | R16: 0 | S16: 0 | T16: 0 | U16: 0 | V16: 0 | W16: 0 | X16: 0 | Y16: 0 | AA16: 1 | AB16: 0 | AC16: 1 | AD16: 0.2 | AE16: 0 | AF16: 0 | AH16: 1 | AI16: 0.73 | AJ16: 1 | AK16: 0.73 | AL16: 0 | AN16: 0 | AO16: 0.73 | AP16: 0 | AQ16: 0 | AR16: 0 | AS16: 0 | AT16: 0 | AU16: 0 | AV16: 0 | AW16: 0 | AX16: 10 | AY16: 5 | AZ16: 5 | BA16: 1 | BB16: 0 | BC16: 0 | BD16: 0.25641 | BE16: 5 | BF16: 2 | BG16: 0 | BI16: 0 | BJ16: 0 | BK16: 0 | BL16: 0 | BO16: 0 | BP16: 0 | BQ16: 0 | BR16: 0 | BS16: 0 | BT16: 0
A17: 46104 | B17: 992234348721 | C17: 商品 | D17: LENNEA冬季新款绞花针织拼接长袖波点棉服女上衣保暖短外套棉衣 | E17: 142 | F17: 16 | G17: 1.68 | H17: 0.11268 | I17: 0.11 | J17: 11.83 | K17: 0 | L17: 0 | M17: 0 | N17: 0 | O17: 0 | P17: 0 | Q17: 0 | R17: 0 | S17: 0 | T17: 0 | U17: 0 | V17: 0 | W17: 0 | X17: 0 | Y17: 0 | AA17: 1 | AB17: 0 | AC17: 1 | AD17: 0.0625 | AE17: 0 | AF17: 0 | AH17: 1 | AI17: 1.68 | AJ17: 1 | AK17: 1.68 | AL17: 0 | AN17: 0 | AO17: 1.68 | AP17: 0 | AQ17: 0 | AR17: 0 | AS17: 0 | AT17: 0 | AU17: 0 | AV17: 0 | AW17: 0 | AX17: 31 | AY17: 16 | AZ17: 14 | BA17: 0.875 | BB17: 0 | BC17: 0 | BD17: 0.21831 | BE17: 14 | BF17: 2 | BG17: 0 | BI17: 0 | BJ17: 0 | BK17: 0 | BL17: 0 | BO17: 0 | BP17: 0 | BQ17: 0 | BR17: 0 | BS17: 0 | BT17: 0
A18: 46104 | B18: 988780710366 | C18: 商品 | D18: LENNEA小香风白色外套女春2025新款深秋初冬高级短款羊毛感上衣 | E18: 190 | F18: 10 | G18: 3 | H18: 0.05263 | I18: 0.3 | J18: 15.79 | K18: 0 | L18: 0 | M18: 0 | N18: 0 | O18: 0 | P18: 0 | Q18: 0 | R18: 0 | S18: 0 | T18: 0 | U18: 0 | V18: 0 | W18: 0 | X18: 0 | Y18: 0 | AA18: 0 | AB18: 0 | AC18: 0 | AD18: 0 | AE18: 0 | AF18: 0 | AH18: 0 | AJ18: 0 | AL18: 0 | AN18: 0 | AP18: 0 | AQ18: 0 | AR18: 0 | AS18: 0 | AT18: 0 | AU18: 0 | AV18: 0 | AW18: 0 | AX18: 15 | AY18: 10 | AZ18: 8 | BA18: 0.8 | BB18: 0 | BC18: 0 | BD18: 0.07895 | BE18: 5 | BF18: 2 | BG18: 0 | BI18: 0 | BJ18: 0 | BK18: 0 | BL18: 0 | BO18: 0 | BP18: 0 | BQ18: 0 | BR18: 0 | BS18: 0 | BT18: 0
A19: 46104 | B19: 987169874467 | C19: 商品 | D19: LENNEA毛领双排扣短款毛呢羊毛大衣连帽外套女收腰秋冬加厚上衣 | E19: 59 | F19: 2 | G19: 0.33 | H19: 0.0339 | I19: 0.17 | J19: 5.59 | K19: 0 | L19: 0 | M19: 0 | N19: 0 | O19: 0 | P19: 0 | Q19: 0 | R19: 0 | S19: 0 | T19: 0 | U19: 0 | V19: 0 | W19: 0 | X19: 0 | Y19: 0 | AA19: 0 | AB19: 0 | AC19: 0 | AD19: 0 | AE19: 0 | AF19: 0 | AH19: 0 | AJ19: 0 | AL19: 0 | AN19: 0 | AP19: 0 | AQ19: 0 | AR19: 0 | AS19: 0 | AT19: 0 | AU19: 0 | AV19: 0 | AW19: 0 | AX19: 9 | AY19: 2 | AZ19: 2 | BA19: 1 | BB19: 0 | BC19: 0 | BD19: 0.15254 | BE19: 7 | BF19: 5 | BG19: 0 | BI19: 0 | BJ19: 0 | BK19: 0 | BL19: 0 | BO19: 0 | BP19: 0 | BQ19: 0 | BR19: 0 | BS19: 0 | BT19: 0
A20: 46104 | B20: 986610503692 | C20: 商品 | D20: LENNEA毛毛外套女冬季短款翻领正肩皮毛一体环保毛皮草上衣女冬 | E20: 167 | F20: 14 | G20: 1.17 | H20: 0.08383 | I20: 0.08 | J20: 7.01 | K20: 0 | L20: 0 | M20: 0 | N20: 0 | O20: 0 | P20: 0 | Q20: 0 | R20: 0 | S20: 0 | T20: 0 | U20: 0 | V20: 0 | W20: 0 | X20: 0 | Y20: 0 | AA20: 1 | AB20: 1 | AC20: 0 | AD20: 0.07143 | AE20: 0 | AF20: 0 | AH20: 1 | AI20: 1.17 | AJ20: 1 | AK20: 1.17 | AL20: 0 | AN20: 0 | AO20: 1.17 | AP20: 0 | AQ20: 0 | AR20: 0 | AS20: 0 | AT20: 0 | AU20: 0 | AV20: 0 | AW20: 0 | AX20: 29 | AY20: 12 | AZ20: 7 | BA20: 0.58333 | BB20: 0 | BC20: 0 | BD20: 0.17365 | BE20: 14 | BF20: 2 | BG20: 0 | BI20: 0 | BJ20: 0 | BK20: 0 | BL20: 0 | BO20: 0 | BP20: 0 | BQ20: 0 | BR20: 0 | BS20: 0 | BT20: 0
A21: 46104 | B21: 972548387983 | C21: 商品 | D21: LENNEA藏青色毛领连帽棉服女冬季新款宽松保暖小个子百搭棉衣外套 | E21: 53 | F21: 2 | G21: 2.2 | H21: 0.03774 | I21: 1.1 | J21: 41.51 | K21: 0 | L21: 0 | M21: 0 | N21: 0 | O21: 0 | P21: 0 | Q21: 0 | R21: 0 | S21: 0 | T21: 0 | U21: 0 | V21: 0 | W21: 0 | X21: 0 | Y21: 0 | AA21: 0 | AB21: 0 | AC21: 0 | AD21: 0 | AE21: 0 | AF21: 0 | AH21: 0 | AJ21: 0 | AL21: 0 | AN21: 0 | AP21: 0 | AQ21: 0 | AR21: 0 | AS21: 0 | AT21: 0 | AU21: 0 | AV21: 0 | AW21: 0 | AX21: 8 | AY21: 2 | AZ21: 2 | BA21: 1 | BB21: 0 | BC21: 0 | BD21: 0.15094 | BE21: 6 | BF21: 4 | BG21: 0 | BI21: 0 | BJ21: 0 | BK21: 0 | BL21: 0 | BO21: 0 | BP21: 0 | BQ21: 0 | BR21: 0 | BS21: 0 | BT21: 0
A22: 46104 | B22: 970286397535 | C22: 商品 | D22: LENNEA小香风外套女秋冬2025新款深秋初冬高级短款羊毛感上衣春 | E22: 511 | F22: 24 | G22: 6.4 | H22: 0.04697 | I22: 0.27 | J22: 12.52 | K22: 0 | L22: 0 | M22: 0 | N22: 0 | O22: 0 | P22: 0 | Q22: 0 | R22: 0 | S22: 0 | T22: 0 | U22: 0 | V22: 0 | W22: 0 | X22: 0 | Y22: 0 | AA22: 0 | AB22: 0 | AC22: 0 | AD22: 0 | AE22: 0 | AF22: 0 | AH22: 0 | AJ22: 0 | AL22: 0 | AN22: 0 | AP22: 0 | AQ22: 0 | AR22: 0 | AS22: 0 | AT22: 0 | AU22: 0 | AV22: 0 | AW22: 1 | AX22: 48 | AY22: 24 | AZ22: 19 | BA22: 0.79167 | BB22: 0 | BC22: 0 | BD22: 0.09393 | BE22: 24 | BF22: 2 | BG22: 0 | BI22: 0 | BJ22: 0 | BK22: 0 | BL22: 0 | BO22: 0 | BP22: 0 | BQ22: 0 | BR22: 0 | BS22: 0 | BT22: 0
A23: 46104 | B23: 969105067992 | C23: 商品 | D23: LENNEA气质大毛领羽绒服外套女秋冬季连帽毛呢上衣小个子夹棉保暖 | E23: 492 | F23: 34 | G23: 8.99 | H23: 0.06911 | I23: 0.26 | J23: 18.27 | K23: 0 | L23: 0 | M23: 0 | N23: 0 | O23: 0 | P23: 0 | Q23: 0 | R23: 0 | S23: 0 | T23: 0 | U23: 0 | V23: 0 | W23: 0 | X23: 0 | Y23: 0 | AA23: 1 | AB23: 1 | AC23: 0 | AD23: 0.02941 | AE23: 0 | AF23: 0 | AH23: 1 | AI23: 8.99 | AJ23: 1 | AK23: 8.99 | AL23: 0 | AN23: 0 | AO23: 8.99 | AP23: 0 | AQ23: 0 | AR23: 0 | AS23: 0 | AT23: 0 | AU23: 0 | AV23: 0 | AW23: 0 | AX23: 47 | AY23: 30 | AZ23: 26 | BA23: 0.86667 | BB23: 0 | BC23: 0 | BD23: 0.09553 | BE23: 13 | BF23: 2 | BG23: 0 | BI23: 0 | BJ23: 0 | BK23: 0 | BL23: 0 | BO23: 0 | BP23: 0 | BQ23: 0 | BR23: 0 | BS23: 0 | BT23: 0
A24: 46104 | B24: 966724894105 | C24: 商品 | D24: LENNEA灰色彩点镶钻毛衣外套女针织开衫miu系高级感软糯上衣外套 | E24: 1187 | F24: 64 | G24: 13.17 | H24: 0.05392 | I24: 0.21 | J24: 11.1 | K24: 0 | L24: 0 | M24: 0 | N24: 0 | O24: 0 | P24: 0 | Q24: 0 | R24: 176 | S24: 176 | T24: 1 | U24: 0 | V24: 1 | W24: 0.01563 | X24: 13.36 | Y24: 13.36 | Z24: 13.17 | AA24: 8 | AB24: 4 | AC24: 4 | AD24: 0.125 | AE24: 1 | AF24: 1 | AG24: 13.17 | AH24: 10 | AI24: 1.32 | AJ24: 9 | AK24: 1.46 | AL24: 2 | AM24: 13.17 | AN24: 0.01563 | AO24: 1.65 | AP24: 1 | AQ24: 208 | AR24: 0 | AS24: 1 | AT24: 0 | AU24: 0 | AV24: 0 | AW24: 0 | AX24: 182 | AY24: 62 | AZ24: 48 | BA24: 0.77419 | BB24: 0 | BC24: 0 | BD24: 0.15333 | BE24: 114 | BF24: 3 | BG24: 1 | BH24: 1 | BI24: 0 | BJ24: 0 | BK24: 0 | BL24: 1 | BM24: 1 | BN24: 176 | BO24: 0 | BP24: 0 | BQ24: 0 | BR24: 0 | BS24: 0 | BT24: 0
A25: 46104 | B25: 959252941279 | C25: 商品 | D25: LENNEA波点花边袖黑色长袖针织开衫女miu系修身打底衫早秋上衣春 | E25: 86109 | F25: 4526 | G25: 1672.86 | H25: 0.05256 | I25: 0.37 | J25: 19.43 | K25: 0 | L25: 0 | M25: 0 | N25: 0 | O25: 0 | P25: 0 | Q25: 17650 | R25: 2974 | S25: 20624 | T25: 138 | U25: 121 | V25: 17 | W25: 0.03049 | X25: 12.33 | Y25: 12.33 | Z25: 12.12 | AA25: 657 | AB25: 528 | AC25: 129 | AD25: 0.14516 | AE25: 107 | AF25: 44 | AG25: 38.02 | AH25: 808 | AI25: 2.07 | AJ25: 764 | AK25: 2.19 | AL25: 151 | AM25: 15.63 | AN25: 0.02364 | AO25: 2.55 | AP25: 149 | AQ25: 26206 | AR25: 90 | AS25: 17 | AT25: 0 | AU25: 0 | AV25: 0 | AW25: 27 | AX25: 12126 | AY25: 4198 | AZ25: 3405 | BA25: 0.8111 | BB25: 0 | BC25: 0 | BD25: 0.14082 | BE25: 7127 | BF25: 3 | BG25: 75 | BH25: 0.98684 | BI25: 0 | BJ25: 0 | BK25: 0 | BL25: 76 | BM25: 2 | BN25: 271.37 | BO25: 0 | BP25: 0 | BQ25: 0 | BR25: 0 | BS25: 0 | BT25: 0
A26: 46104 | B26: 952989667628 | C26: 商品 | D26: LENNEA白色牛仔裤女宽松垂感阔腿裤高腰显瘦休闲百搭拖地长裤子 | E26: 1334 | F26: 165 | G26: 63.56 | H26: 0.12369 | I26: 0.39 | J26: 47.65 | K26: 0 | L26: 0 | M26: 0 | N26: 0 | O26: 0 | P26: 0 | Q26: 0 | R26: 0 | S26: 0 | T26: 0 | U26: 0 | V26: 0 | W26: 0 | X26: 0 | Y26: 0 | AA26: 42 | AB26: 2 | AC26: 40 | AD26: 0.25455 | AE26: 7 | AF26: 5 | AG26: 12.71 | AH26: 54 | AI26: 1.18 | AJ26: 49 | AK26: 1.3 | AL26: 12 | AM26: 9.08 | AN26: 0.04242 | AO26: 1.51 | AP26: 0 | AQ26: 0 | AR26: 0 | AS26: 7 | AT26: 0 | AU26: 0 | AV26: 0 | AW26: 6 | AX26: 906 | AY26: 156 | AZ26: 141 | BA26: 0.90385 | BB26: 0 | BC26: 0 | BD26: 0.67916 | BE26: 733 | BF26: 6 | BG26: 0 | BI26: 0 | BJ26: 0 | BK26: 0 | BL26: 0 | BO26: 0 | BP26: 0 | BQ26: 0 | BR26: 0 | BS26: 0 | BT26: 0
A27: 46104 | B27: 949754058834 | C27: 商品 | D27: LENNEA黑色小香风外套女短款长袖针织开衫气质高级感排扣外套上衣 | E27: 3108 | F27: 299 | G27: 68.84 | H27: 0.0962 | I27: 0.23 | J27: 22.15 | K27: 0 | L27: 0 | M27: 0 | N27: 0 | O27: 0 | P27: 0 | Q27: 672 | R27: 485 | S27: 1157 | T27: 7 | U27: 4 | V27: 3 | W27: 0.02341 | X27: 16.81 | Y27: 16.81 | Z27: 9.83 | AA27: 66 | AB27: 7 | AC27: 59 | AD27: 0.22074 | AE27: 16 | AF27: 10 | AG27: 6.88 | AH27: 92 | AI27: 0.75 | AJ27: 82 | AK27: 0.84 | AL27: 26 | AM27: 4.3 | AN27: 0.05351 | AO27: 1.04 | AP27: 8 | AQ27: 1563 | AR27: 2 | AS27: 14 | AT27: 0 | AU27: 0 | AV27: 0 | AW27: 5 | AX27: 1266 | AY27: 283 | AZ27: 250 | BA27: 0.88339 | BB27: 0 | BC27: 0 | BD27: 0.40734 | BE27: 948 | BF27: 4 | BG27: 5 | BH27: 1 | BI27: 0 | BJ27: 0 | BK27: 0 | BL27: 5 | BM27: 1 | BN27: 231.4 | BO27: 0 | BP27: 0 | BQ27: 0 | BR27: 0 | BS27: 0 | BT27: 0
A28: 46104 | B28: 949034219575 | C28: 商品 | D28: LENNEA慵懒感减龄海军领毛衣女秋季温柔设计感学院风针织上衣女春 | E28: 2070 | F28: 121 | G28: 24.27 | H28: 0.05845 | I28: 0.2 | J28: 11.72 | K28: 0 | L28: 0 | M28: 0 | N28: 0 | O28: 0 | P28: 0 | Q28: 0 | R28: 0 | S28: 0 | T28: 0 | U28: 0 | V28: 0 | W28: 0 | X28: 0 | Y28: 0 | AA28: 8 | AB28: 5 | AC28: 3 | AD28: 0.06612 | AE28: 2 | AF28: 0 | AH28: 10 | AI28: 2.43 | AJ28: 10 | AK28: 2.43 | AL28: 2 | AM28: 12.14 | AN28: 0.01653 | AO28: 3.03 | AP28: 0 | AQ28: 0 | AR28: 2 | AS28: 0 | AT28: 0 | AU28: 0 | AV28: 0 | AW28: 0 | AX28: 252 | AY28: 119 | AZ28: 92 | BA28: 0.77311 | BB28: 0 | BC28: 0 | BD28: 0.12174 | BE28: 103 | BF28: 2 | BG28: 0 | BI28: 0 | BJ28: 0 | BK28: 0 | BL28: 0 | BO28: 0 | BP28: 0 | BQ28: 0 | BR28: 0 | BS28: 0 | BT28: 0
A29: 46104 | B29: 926919925240 | C29: 商品 | D29: LENNEA粉色蓬蓬花苞半身裙女夏季新款设计感高腰显瘦a字芭蕾裤裙 | E29: 564 | F29: 31 | G29: 9.93 | H29: 0.05496 | I29: 0.32 | J29: 17.61 | K29: 0 | L29: 0 | M29: 0 | N29: 0 | O29: 0 | P29: 0 | Q29: 0 | R29: 0 | S29: 0 | T29: 0 | U29: 0 | V29: 0 | W29: 0 | X29: 0 | Y29: 0 | AA29: 2 | AB29: 0 | AC29: 2 | AD29: 0.06452 | AE29: 3 | AF29: 0 | AH29: 5 | AI29: 1.99 | AJ29: 5 | AK29: 1.99 | AL29: 3 | AM29: 3.31 | AN29: 0.09677 | AO29: 4.97 | AP29: 0 | AQ29: 0 | AR29: 3 | AS29: 0 | AT29: 0 | AU29: 0 | AV29: 0 | AW29: 0 | AX29: 50 | AY29: 29 | AZ29: 28 | BA29: 0.96552 | BB29: 0 | BC29: 0 | BD29: 0.08865 | BE29: 19 | BF29: 2 | BG29: 0 | BI29: 0 | BJ29: 0 | BK29: 0 | BL29: 0 | BO29: 0 | BP29: 0 | BQ29: 0 | BR29: 0 | BS29: 0 | BT29: 0
A30: 46104 | B30: 920335022314 | C30: 商品 | D30: LENNEA法式拼接连衣裙女夏季新款简约气质收腰显瘦无袖小众裙子 | E30: 327 | F30: 20 | G30: 4.3 | H30: 0.06116 | I30: 0.22 | J30: 13.15 | K30: 0 | L30: 0 | M30: 0 | N30: 0 | O30: 0 | P30: 0 | Q30: 0 | R30: 0 | S30: 0 | T30: 0 | U30: 0 | V30: 0 | W30: 0 | X30: 0 | Y30: 0 | AA30: 7 | AB30: 0 | AC30: 7 | AD30: 0.35 | AE30: 1 | AF30: 2 | AG30: 2.15 | AH30: 10 | AI30: 0.43 | AJ30: 8 | AK30: 0.54 | AL30: 3 | AM30: 4.3 | AN30: 0.05 | AO30: 0.61 | AP30: 0 | AQ30: 0 | AR30: 0 | AS30: 1 | AT30: 0 | AU30: 0 | AV30: 0 | AW30: 0 | AX30: 97 | AY30: 20 | AZ30: 16 | BA30: 0.8 | BB30: 0 | BC30: 0 | BD30: 0.29664 | BE30: 76 | BF30: 5 | BG30: 0 | BI30: 0 | BJ30: 0 | BK30: 0 | BL30: 0 | BO30: 0 | BP30: 0 | BQ30: 0 | BR30: 0 | BS30: 0 | BT30: 0
A31: 46104 | B31: 905381044899 | C31: 商品 | D31: LENNEA法式小个子设计感减龄黄色连衣裙子女夏季无袖背心花苞短裙 | E31: 120444 | F31: 5680 | G31: 1262.24 | H31: 0.04716 | I31: 0.22 | J31: 10.48 | K31: 0 | L31: 0 | M31: 0 | N31: 0 | O31: 0 | P31: 0 | Q31: 3889 | R31: 0 | S31: 3889 | T31: 22 | U31: 22 | V31: 0 | W31: 0.00387 | X31: 3.08 | Y31: 3.08 | Z31: 57.37 | AA31: 398 | AB31: 359 | AC31: 39 | AD31: 0.07007 | AE31: 153 | AF31: 26 | AG31: 48.55 | AH31: 577 | AI31: 2.19 | AJ31: 551 | AK31: 2.29 | AL31: 179 | AM31: 8.25 | AN31: 0.02694 | AO31: 3.17 | AP31: 22 | AQ31: 4596 | AR31: 142 | AS31: 11 | AT31: 0 | AU31: 0 | AV31: 0 | AW31: 15 | AX31: 11229 | AY31: 5357 | AZ31: 4881 | BA31: 0.91114 | BB31: 0 | BC31: 0 | BD31: 0.09323 | BE31: 5008 | BF31: 2 | BG31: 22 | BH31: 1 | BI31: 0 | BJ31: 0 | BK31: 0 | BL31: 22 | BM31: 1 | BN31: 176.77 | BO31: 0 | BP31: 0 | BQ31: 0 | BR31: 0 | BS31: 0 | BT31: 0
A32: 46104 | B32: 905004041827 | C32: 商品 | D32: LENNEA原创蕾丝荡领短袖t恤女夏季纯欲设计感斜肩别致韩系上衣 | E32: 1996 | F32: 94 | G32: 33.49 | H32: 0.04709 | I32: 0.36 | J32: 16.78 | K32: 0 | L32: 0 | M32: 0 | N32: 0 | O32: 0 | P32: 0 | Q32: 0 | R32: 0 | S32: 0 | T32: 0 | U32: 0 | V32: 0 | W32: 0 | X32: 0 | Y32: 0 | AA32: 6 | AB32: 2 | AC32: 4 | AD32: 0.06383 | AE32: 3 | AF32: 0 | AH32: 9 | AI32: 3.72 | AJ32: 9 | AK32: 3.72 | AL32: 3 | AM32: 11.16 | AN32: 0.03191 | AO32: 5.58 | AP32: 0 | AQ32: 0 | AR32: 2 | AS32: 1 | AT32: 0 | AU32: 0 | AV32: 0 | AW32: 0 | AX32: 187 | AY32: 87 | AZ32: 78 | BA32: 0.89655 | BB32: 0 | BC32: 0 | BD32: 0.09369 | BE32: 91 | BF32: 2 | BG32: 0 | BI32: 0 | BJ32: 0 | BK32: 0 | BL32: 0 | BO32: 0 | BP32: 0 | BQ32: 0 | BR32: 0 | BS32: 0 | BT32: 0
A33: 46104 | B33: 904997441508 | C33: 商品 | D33: LENNEA芭蕾风法式复古低腰花苞a字半身裙女夏季甜美蓬蓬灯笼短裙 | E33: 4436 | F33: 283 | G33: 75.38 | H33: 0.0638 | I33: 0.27 | J33: 16.99 | K33: 0 | L33: 0 | M33: 0 | N33: 0 | O33: 0 | P33: 0 | Q33: 0 | R33: 0 | S33: 0 | T33: 0 | U33: 0 | V33: 0 | W33: 0 | X33: 0 | Y33: 0 | AA33: 14 | AB33: 13 | AC33: 1 | AD33: 0.04947 | AE33: 7 | AF33: 0 | AH33: 21 | AI33: 3.59 | AJ33: 21 | AK33: 3.59 | AL33: 7 | AM33: 10.77 | AN33: 0.02473 | AO33: 5.38 | AP33: 0 | AQ33: 0 | AR33: 6 | AS33: 1 | AT33: 0 | AU33: 0 | AV33: 0 | AW33: 0 | AX33: 425 | AY33: 274 | AZ33: 247 | BA33: 0.90146 | BB33: 0 | BC33: 0 | BD33: 0.09581 | BE33: 136 | BF33: 2 | BG33: 0 | BI33: 0 | BJ33: 0 | BK33: 0 | BL33: 0 | BO33: 0 | BP33: 0 | BQ33: 0 | BR33: 0 | BS33: 0 | BT33: 0
A34: 46104 | B34: 874018241490 | C34: 商品 | D34: LENNEA原创蓝色小香风春秋新款财阀千金风气质收腰开衫毛呢外套女 | E34: 3711 | F34: 225 | G34: 39.26 | H34: 0.06063 | I34: 0.17 | J34: 10.58 | K34: 0 | L34: 0 | M34: 0 | N34: 0 | O34: 0 | P34: 0 | Q34: 0 | R34: 0 | S34: 0 | T34: 0 | U34: 0 | V34: 0 | W34: 0 | X34: 0 | Y34: 0 | AA34: 2 | AB34: 1 | AC34: 1 | AD34: 0.00889 | AE34: 0 | AF34: 0 | AH34: 2 | AI34: 19.63 | AJ34: 2 | AK34: 19.63 | AL34: 0 | AN34: 0 | AO34: 19.63 | AP34: 0 | AQ34: 0 | AR34: 0 | AS34: 0 | AT34: 0 | AU34: 0 | AV34: 0 | AW34: 0 | AX34: 402 | AY34: 222 | AZ34: 173 | BA34: 0.77928 | BB34: 0 | BC34: 0 | BD34: 0.10833 | BE34: 171 | BF34: 2 | BG34: 0 | BI34: 0 | BJ34: 0 | BK34: 0 | BL34: 0 | BO34: 0 | BP34: 0 | BQ34: 0 | BR34: 0 | BS34: 0 | BT34: 0
A35: 46104 | B35: 858672318475 | C35: 商品 | D35: LENNEA蝴蝶结格子拼接设计感宽松直筒拖地高腰牛仔裤女显瘦长裤 | E35: 42 | F35: 5 | G35: 4.51 | H35: 0.11905 | I35: 0.9 | J35: 107.38 | K35: 0 | L35: 0 | M35: 0 | N35: 0 | O35: 0 | P35: 0 | Q35: 185 | R35: 0 | S35: 185 | T35: 1 | U35: 1 | V35: 0 | W35: 0.2 | X35: 41.02 | Y35: 41.02 | Z35: 4.51 | AA35: 2 | AB35: 1 | AC35: 1 | AD35: 0.4 | AE35: 0 | AF35: 0 | AH35: 2 | AI35: 2.26 | AJ35: 2 | AK35: 2.26 | AL35: 0 | AN35: 0 | AO35: 2.26 | AP35: 3 | AQ35: 490 | AR35: 0 | AS35: 0 | AT35: 0 | AU35: 0 | AV35: 0 | AW35: 2 | AX35: 12 | AY35: 4 | AZ35: 3 | BA35: 0.75 | BB35: 0 | BC35: 0 | BD35: 0.28571 | BE35: 7 | BF35: 3 | BG35: 1 | BH35: 1 | BI35: 0 | BJ35: 0 | BK35: 0 | BL35: 1 | BM35: 1 | BN35: 185 | BO35: 0 | BP35: 0 | BQ35: 0 | BR35: 0 | BS35: 0 | BT35: 0
A36: 46104 | B36: 811797505172 | C36: 商品 | D36: LENNEA原创设计感连帽贝壳毛衣开衫针织衫女秋季外套慵懒风上衣春 | E36: 5501 | F36: 456 | G36: 54.94 | H36: 0.08289 | I36: 0.12 | J36: 9.99 | K36: 0 | L36: 0 | M36: 0 | N36: 0 | O36: 0 | P36: 0 | Q36: 0 | R36: 0 | S36: 0 | T36: 0 | U36: 0 | V36: 0 | W36: 0 | X36: 0 | Y36: 0 | AA36: 14 | AB36: 13 | AC36: 1 | AD36: 0.0307 | AE36: 2 | AF36: 0 | AH36: 16 | AI36: 3.43 | AJ36: 16 | AK36: 3.43 | AL36: 2 | AM36: 27.47 | AN36: 0.00439 | AO36: 3.92 | AP36: 0 | AQ36: 0 | AR36: 2 | AS36: 0 | AT36: 0 | AU36: 0 | AV36: 0 | AW36: 0 | AX36: 593 | AY36: 427 | AZ36: 390 | BA36: 0.91335 | BB36: 0 | BC36: 0 | BD36: 0.1078 | BE36: 149 | BF36: 1 | BG36: 0 | BI36: 0 | BJ36: 0 | BK36: 0 | BL36: 0 | BO36: 0 | BP36: 0 | BQ36: 0 | BR36: 0 | BS36: 0 | BT36: 0
A37: 46104 | B37: 763414867633 | C37: 商品 | D37: LENNEA法式气质小香风短款外套女2025秋冬加绒显瘦高级感羽绒上衣 | E37: 8445 | F37: 511 | G37: 151.97 | H37: 0.06051 | I37: 0.3 | J37: 18 | K37: 0 | L37: 0 | M37: 0 | N37: 0 | O37: 0 | P37: 0 | Q37: 1190 | R37: 678 | S37: 1868 | T37: 9 | U37: 5 | V37: 4 | W37: 0.01761 | X37: 12.29 | Y37: 12.29 | Z37: 16.89 | AA37: 76 | AB37: 22 | AC37: 54 | AD37: 0.14873 | AE37: 13 | AF37: 5 | AG37: 30.39 | AH37: 94 | AI37: 1.62 | AJ37: 89 | AK37: 1.71 | AL37: 18 | AM37: 11.69 | AN37: 0.02544 | AO37: 2 | AP37: 10 | AQ37: 2480 | AR37: 4 | AS37: 9 | AT37: 0 | AU37: 0 | AV37: 0 | AW37: 3 | AX37: 1753 | AY37: 485 | AZ37: 406 | BA37: 0.83711 | BB37: 0 | BC37: 0 | BD37: 0.20758 | BE37: 1198 | BF37: 4 | BG37: 7 | BH37: 0.875 | BI37: 0 | BJ37: 0 | BK37: 0 | BL37: 8 | BM37: 1 | BN37: 233.5 | BO37: 0 | BP37: 0 | BQ37: 0 | BR37: 0 | BS37: 0 | BT37: 0
A38: 46104 | B38: 728037000377 | C38: 商品 | D38: LENNEA藏青色原创秋冬无领女正肩修身短款小香风学院夹克外套春季 | E38: 10928 | F38: 589 | G38: 98.86 | H38: 0.0539 | I38: 0.17 | J38: 9.05 | K38: 0 | L38: 0 | M38: 0 | N38: 0 | O38: 0 | P38: 0 | Q38: 1065 | R38: 176 | S38: 1241 | T38: 7 | U38: 6 | V38: 1 | W38: 0.01188 | X38: 12.55 | Y38: 12.55 | Z38: 14.12 | AA38: 35 | AB38: 15 | AC38: 20 | AD38: 0.05942 | AE38: 6 | AF38: 3 | AG38: 32.95 | AH38: 44 | AI38: 2.25 | AJ38: 41 | AK38: 2.41 | AL38: 9 | AM38: 16.48 | AN38: 0.01019 | AO38: 2.82 | AP38: 7 | AQ38: 1462 | AR38: 1 | AS38: 5 | AT38: 0 | AU38: 0 | AV38: 0 | AW38: 3 | AX38: 1072 | AY38: 542 | AZ38: 504 | BA38: 0.92989 | BB38: 0 | BC38: 0 | BD38: 0.0981 | BE38: 476 | BF38: 2 | BG38: 4 | BH38: 1 | BI38: 0 | BJ38: 0 | BK38: 0 | BL38: 4 | BM38: 2 | BN38: 310.25 | BO38: 0 | BP38: 0 | BQ38: 0 | BR38: 0 | BS38: 0 | BT38: 0
A39: 46104 | B39: 728030472469 | C39: 商品 | D39: LENNEA 原创秋冬女长袖通勤宽松宽松高腰学生设计条纹衬衫春 | E39: 3122 | F39: 196 | G39: 17.99 | H39: 0.06278 | I39: 0.09 | J39: 5.76 | K39: 0 | L39: 0 | M39: 0 | N39: 0 | O39: 0 | P39: 0 | Q39: 0 | R39: 0 | S39: 0 | T39: 0 | U39: 0 | V39: 0 | W39: 0 | X39: 0 | Y39: 0 | AA39: 12 | AB39: 1 | AC39: 11 | AD39: 0.06122 | AE39: 1 | AF39: 1 | AG39: 17.99 | AH39: 14 | AI39: 1.29 | AJ39: 13 | AK39: 1.38 | AL39: 2 | AM39: 17.99 | AN39: 0.0051 | AO39: 1.5 | AP39: 0 | AQ39: 0 | AR39: 0 | AS39: 1 | AT39: 0 | AU39: 0 | AV39: 0 | AW39: 0 | AX39: 374 | AY39: 186 | AZ39: 167 | BA39: 0.89785 | BB39: 0 | BC39: 0 | BD39: 0.1198 | BE39: 173 | BF39: 2 | BG39: 0 | BI39: 0 | BJ39: 0 | BK39: 0 | BL39: 0 | BO39: 0 | BP39: 0 | BQ39: 0 | BR39: 0 | BS39: 0 | BT39: 0

Sheet 站外结款表
A1: 月份 | B1: 日期 | C1: 大类 | D1: 项目 | E1: 款式编码（这个要对应商品成本表的编码 然后是通过审核之后直接自动跳出来） | F1: 款式 | G1: 金额 | H1: 寄/送 | I1: 博主名 | J1: 付款金额 | K1: 付款日期 | L1: 衣服成本（抓取对应的商品成本表的） | M1: 总成本（衣服成本加佣金成本） | N1: 付款图片 | O1: 备注
A2: 1月 | B2: 46026 | C2: 站外推广 | D2: 佣金 | F2: 波点棉服 | G2: 1100 | H2: 送 | I2: 小红书：笑榕船长 | J2: 1100 | K2: 46032 | M2: #VALUE!
A3: 1月 | B3: 46026 | C3: 站外推广 | D3: 佣金 | F3: 蝴蝶结条纹棉服 | G3: 400 | H3: 送 | I3: 小红书：小v（宫） | J3: 补发合集前三 | M3: 0
A4: 1月 | B4: 46026 | C4: 站外推广 | D4: 佣金 | F4: 系带麂皮外套 | G4: 100 | H4: 送 | I4: 小红书：黎梓辛 | J4: 100 | K4: 46032 | M4: #VALUE!
A5: 1月 | B5: 46026 | C5: 站外推广 | D5: 佣金 | F5: 大翻领皮草（卡其） | G5: 600 | H5: 送 | I5: 小红书：徐大囍Nancy | J5: 600 | K5: 46032 | M5: #VALUE!
A6: 1月 | B6: 46026 | C6: 站外推广 | D6: 佣金 | F6: 粉色毛领大衣 | G6: 180 | H6: 送 | I6: 小红书：团子不是圆圆的 | J6: 180 | K6: 46032 | M6: #VALUE!
A7: 1月 | B7: 46026 | C7: 站外推广 | D7: 佣金 | F7: 花苞羽绒服 | G7: 600 | H7: 送 | I7: 小红书：鱼鱼很乖 | J7: 600 | K7: 46032 | M7: #VALUE!
A8: 1月 | B8: 46026 | C8: 站外推广 | D8: 佣金 | F8: 条纹羊羔毛 | G8: 200 | H8: 送 | I8: 小红书：姜姜好困 | J8: 200 | K8: 46032 | M8: #VALUE!
A9: 1月 | B9: 46026 | C9: 站外推广 | D9: 佣金 | F9: 双排扣外套 | G9: 100 | H9: 送 | I9: 小红书：张芽芽 | J9: 100 | K9: 46032 | M9: #VALUE!
A10: 1月 | B10: 46026 | C10: 站外推广 | D10: 佣金 | F10: 系带麂皮外套 | G10: 710 | H10: 送 | I10: 小红书：都没有李甜 | J10: 710 | K10: 46032 | M10: #VALUE!
A11: 1月 | B11: 46026 | C11: 站外推广 | D11: 佣金 | F11: 双排扣外套 | G11: 800 | H11: 送 | I11: 小红书：啊喔开饭没 | J11: 800 | K11: 46032 | M11: #VALUE!
A12: 1月 | B12: 46026 | C12: 站外推广 | D12: 佣金 | F12: 木耳边棉服 | G12: 80 | H12: 送 | I12: 小红书：酱子西子 | J12: 80 | K12: 46032 | M12: #VALUE!
A13: 1月 | B13: 46026 | C13: 站外推广 | D13: 佣金 | F13: 大翻领皮草（卡其） | G13: 100 | H13: 已寄回 | I13: 小红书：涵涵爱拍照 | J13: 50 | K13: 46032 | M13: 100
A14: 1月 | B14: 46026 | C14: 站外推广 | D14: 佣金 | F14: 菲奥娜棉服 | G14: 250 | H14: 送 | I14: 小红书：奇妙小0 | J14: 补发 | M14: 0
A15: 1月 | B15: 46026 | C15: 站外推广 | D15: 佣金 | F15: 毛领棉服（蓝） | G15: 260 | H15: 送 | I15: 小红书：162的糕糕 | J15: 260 | K15: 46032 | M15: #VALUE!
A16: 1月 | B16: 46026 | C16: 站外推广 | D16: 佣金 | F16: 大翻领皮草（卡其） | G16: 730 | H16: 送 | I16: 抖音：我想吃西柚 | J16: 730 | K16: 46032 | M16: #VALUE!
A17: 1月 | B17: 46026 | C17: 站外推广 | D17: 佣金 | F17: 粉色毛领大衣 | G17: 300 | H17: 送 | I17: 小红书：莫娣 | J17: 300 | K17: 46032 | M17: #VALUE!
A18: 1月 | B18: 46026 | C18: 站外推广 | D18: 佣金 | F18: 双排扣外套 | G18: 300 | H18: 送 | I18: 小红书：好好酱 | J18: 300 | K18: 46032 | M18: #VALUE!
A19: 1月 | B19: 46026 | C19: 站外推广 | D19: 佣金 | F19: 收腰羽绒服 | G19: 550 | H19: 送 | I19: 小红书：柏含. | J19: 550 | K19: 46032 | M19: #VALUE!
A20: 1月 | B20: 46026 | C20: 站外推广 | D20: 佣金 | F20: 双排扣外套 | G20: 250 | H20: 已寄回 | I20: 小红书：被小帅骗走250万 | J20: 二维码失效 | M20: 250
A21: 1月 | B21: 46026 | C21: 站外推广 | D21: 佣金 | F21: 毛领棉服 | G21: 180 | H21: 送 | I21: 小红书：两个圈 | J21: 180 | K21: 46032 | M21: 180
A22: 1月 | B22: 46026 | C22: 站外推广 | D22: 佣金 | F22: 波点棉服 | G22: 900 | H22: 送 | I22: 小红书：一只鲸 | J22: 900 | K22: 46032 | M22: 900
A23: 1月 | B23: 46026 | C23: 站外推广 | D23: 佣金 | F23: 棕色大衣 | G23: 80 | H23: 已寄回 | I23: 小红书：罗汉果ii | J23: 80 | K23: 46032 | M23: 80
A24: 1月 | B24: 46026 | C24: 站外推广 | D24: 佣金 | F24: 棕色大衣（米色） | G24: 250 | H24: 送 | I24: 小红书：153的多多 | J24: 250 | K24: 46033 | M24: 250
A25: 1月 | B25: 46026 | C25: 站外推广 | D25: 佣金 | F25: 木耳边棉服 | G25: 180 | H25: 送 | I25: 小红书：冻冻荔 | J25: 补发 | M25: 0
A26: 1月 | B26: 46026 | C26: 站外推广 | D26: 佣金 | F26: 木耳边棉服 | G26: 100 | H26: 爆文奖励 | I26: 小红书：小椿 | J26: 100 | K26: 46032 | M26: 100
A27: 1月 | B27: 46026 | C27: 站外推广 | D27: 佣金 | F27: 棕色大衣 | G27: 300 | H27: 送 | I27: 小红书：Hikoy | J27: 300 | K27: 46033 | M27: 300
A28: 1月 | B28: 46026 | C28: 站外推广 | D28: 佣金 | F28: 棕色大衣 | G28: 500 | H28: 送 | I28: 小红书：子川木 | J28: 500 | K28: 46033 | M28: 500
A29: 1月 | B29: 46026 | C29: 站外推广 | D29: 佣金 | F29: 波点棉服 | G29: 90 | H29: 送 | I29: 小红书：睡够12h | J29: 90 | K29: 46032 | M29: 90
A30: 1月 | B30: 46026 | C30: 站外推广 | D30: 佣金 | F30: 粉色毛领大衣 | G30: 150 | H30: 已寄回 | I30: 小红书：一只小羊羔 | J30: 150 | K30: 46032 | M30: 150
A31: 1月 | B31: 46026 | C31: 站外推广 | D31: 佣金 | F31: 贝壳毛衣 | G31: 200 | H31: 送 | I31: 小红书：木头怪兽 | J31: 200 | K31: 46033 | M31: 200
A32: 1月 | B32: 46026 | C32: 站外推广 | D32: 佣金 | F32: 羊绒圈小香风 | G32: 60 | H32: 已寄回 | I32: 小红书：一只雪 | J32: 120 | K32: 46033 | M32: 60
A33: 1月 | B33: 46026 | C33: 站外推广 | D33: 佣金 | F33: 棕色大衣 | G33: 60 | H33: 已寄回 | I33: 小红书：一只雪 | M33: 60
A34: 1月 | B34: 46026 | C34: 站外推广 | D34: 佣金 | F34: 毛领棉服（蓝） | G34: 300 | H34: 送 | I34: 小红书：小羊没烦恼 | J34: 300 | K34: 46032 | M34: 300
A35: 1月 | B35: 46026 | C35: 站外推广 | D35: 佣金 | F35: 花苞羽绒服 | G35: 300 | H35: 送 | I35: 小红书：刘梦梦 | J35: 300 | K35: 46032 | M35: 300
A36: 1月 | B36: 46026 | C36: 站外推广 | D36: 佣金 | F36: 粉色毛领大衣 | G36: 100 | H36: 已寄回 | I36: 小红书：祝泥泥 | J36: 100 | K36: 46032 | M36: 100
A37: 1月 | B37: 46026 | C37: 站外推广 | D37: 佣金 | F37: 波点棉服 | G37: 100 | H37: 已寄回 | I37: 小红书：祝泥泥 | J37: 100 | K37: 46033 | M37: 100
A38: 1月 | B38: 46026 | C38: 站外推广 | D38: 佣金 | F38: 粉色毛领大衣 | G38: 400 | H38: 送 | I38: 小红书：纯情小绵羊 | J38: 400 | K38: 46033 | M38: 400
A39: 1月 | B39: 46026 | C39: 站外推广 | D39: 佣金 | F39: 双排扣外套 | G39: 600 | H39: 送 | I39: 小红书：小绿小绿 | J39: 600 | K39: 46033 | M39: 600
A40: 1月 | B40: 46026 | C40: 站外推广 | D40: 佣金 | F40: 波点棉服 | G40: 260 | H40: 送 | I40: 小红书：别烦凡凡 | J40: 260 | K40: 46033 | M40: 260
...

Sheet 站外推广表
A1: 重复后是否双平台 | B1: 检查是否重复 | C1: 负责PR | D1: 品名 | E1: 货号 | F1: 打单地址 | G1: 发货单号 | H1: 发货时间（填了发货单号的时间） | I1: 合作平台 | J1: 报价 | K1: 博主id | L1: 合作日期 | M1: 送达时间（发货时间+3天） | N1: 预定发布日期 | O1: 线上填订单号，线下填线下 | P1: 素人<1W粉丝KOC<10W粉丝KOL>10W粉丝 | Q1: 微信 | R1: 是否催发 自动生成 | S1: 是否召回 | T1: 寄回单号 | U1: 合作方式 | V1: 合作形式 | W1: 是否发布 | X1: 发布日期 | Y1: 发布链接 | Z1: 点赞量（发布7天后统计） | AA1: 收藏数 | AB1: 评论数 | AC1: 爆文（点赞过千） | AD1: 博主风格 | AE1: 买家秀发布（截图） | AF1: 是否报价过千 | AG1: 约篇月份 | AH1: 合作月份 | AI1: 发布剩余时间 | AJ1: 总成本 | AK1: 颜色 | AL1: 去重后点赞量 | AM1: 去重后实际点赞量（抖音➗️10） | AN1: 收藏赞比 | AO1: 单件点赞成本
C2: 阿咩 | D2: 飘带挂脖上衣 | E2: 2025320 | F2: 尺码：s 收件人: 陈虹羽 手机号码: 13307502767 所在地区: 海南省海口市美兰区海甸街道 详细地址: 中大公寓 | G2: YT7613967120582 | I2: 小红书 | J2: 80 | K2: #NAME? | L2: 46086 | N2: 46122 | P2: KOC | Q2: free-tu00 | R2: 超时 | U2: 送拍 | V2: 单篇 | W2: 未发布 | AC2: 否 | AF2: 否 | AI2: 超时 | AJ2: 125 | AL2: 0 | AN2: 0 | AO2: 0
C3: HE | D3: 斜门襟衬衫 | E3: 2026001 | I3: 小红书 | J3: 160 | K3: 左耳 | L3: 46084 | N3: 46132 | P3: 素人 | Q3: JIANGLT027 | R3: 已发布 | S3: 召回成功 | T3: 435124468134001 | U3: 寄拍 | V3: 单篇 | W3: 已发布 | X3: 46126 | Y3: https://www.xiaohongshu.com/discovery/item/69d9e40c000000001f000eb8?source=webshare&xhsshare=pc_web&xsec_token=CBY9JIjTrfeerO7FXYzvE_MpcVTNih1dd9q0wDXFFH1MQ=&xsec_source=pc_share | Z3: 30 | AA3: 11 | AB3: 6 | AC3: 否 | AF3: 否 | AI3: 已发布 | AJ3: 205 | AL3: 30 | AM3: 30 | AN3: 0.36666667 | AO3: 6.8333333
B4: 重复 | C4: 果片 | D4: 荷叶边沙滩裙 | E4: 2025322 | F4: 尺码：m 地址：安徽省合肥市庐阳区四里河畔小区D区（东苑）小王18225865706 | G4: YT7609046121616 | I4: 小红书 | J4: 150 | K4: 最后一只恐龙🦕 | L4: 46095 | N4: 46142 | P4: 素人 | Q4: Outs1dersXx | R4: 档期内 | U4: 送拍 | V4: 单篇 | W4: 未发布 | AC4: 否 | AF4: 否 | AI4: 12 | AJ4: 240 | AL4: 0 | AN4: 0 | AO4: 0
B5: 重复 | C5: 果片 | D5: 荷叶边沙滩上衣 | E5: 2025322 | F5: 尺码：m 地址：安徽省合肥市庐阳区四里河畔小区D区（东苑）小王18225865706 | G5: YT7609046121616 | I5: 小红书 | J5: 150 | K5: 最后一只恐龙🦕 | L5: 46095 | N5: 46142 | P5: 素人 | Q5: Outs1dersXx | R5: 档期内 | U5: 送拍 | V5: 单篇 | W5: 未发布 | AC5: 否 | AF5: 否 | AI5: 12 | AJ5: 240 | AL5: 0 | AN5: 0 | AO5: 0
C6: 一号 | D6: 飘带挂脖上衣 | E6: 2025320 | F6: 尺码：s 王一 15631415107 河北省邯郸市肥乡区肥乡镇广安路西97号自然资源和规划局 | G6: 已登记 | I6: 小红书 | J6: 110 | K6: 卓子 | L6: 46087 | N6: 46132 | P6: 素人 | Q6: grey5107 | R6: 重要催发 | U6: 送拍 | V6: 单篇 | W6: 未发布 | AC6: 否 | AF6: 否 | AI6: 2 | AJ6: 155 | AL6: 0 | AN6: 0 | AO6: 0
C7: 一号 | D7: 牛仔短裙 | E7: 2026014 | F7: 尺码：s 王一 15631415107 河北省邯郸市肥乡区肥乡镇广安路西97号自然资源和规划局 | G7: 已登记 | I7: 小红书 | J7: 0 | K7: 卓子 | L7: 46087 | N7: 46132 | P7: 素人 | Q7: grey5107 | R7: 重要催发 | U7: 送拍 | V7: 单篇 | W7: 未发布 | AC7: 否 | AF7: 否 | AI7: 2 | AJ7: 45 | AL7: 0 | AN7: 0 | AO7: 0
C8: 一号 | D8: 斜门襟衬衫 | E8: 2026001 | F8: 尺码：s 王一 15631415107 河北省邯郸市肥乡区肥乡镇广安路西97号自然资源和规划局 | G8: YT7609478404279 | I8: 小红书 | J8: 110 | K8: 卓子 | L8: 46087 | N8: 46122 | P8: 素人 | Q8: grey5107 | R8: 已发布 | U8: 送拍 | V8: 单篇 | W8: 已发布 | X8: 46119 | Y8: https://www.xiaohongshu.com/explore/69d52323000000001f0052d7?xsec_token=ABc40NZd4VQaEG2duM-PVO79YNIEAE8jj_Jutj6-vap5M=&xsec_source=pc_search&source=web_search_result_notes | Z8: 53 | AA8: 8 | AB8: 10 | AC8: 否 | AF8: 否 | AI8: 已发布 | AJ8: 155 | AL8: 53 | AM8: 53 | AN8: 0.1509434 | AO8: 2.9245283
